Workbook

Sheet ECNP
C1: ETAT DE CONFORMITE AUX NORMES PRUDENTIELLES
A5: N°CODE | B5: N° | C5: LISTE DES NORMES PRUDENTIELLES | F5: Niveau à respecter (1) | G5: Niveau observé (2)
B6: 1 | C6: NORMES DE SOLVABILITE
A7: RA0_001 | B7: 1.1 | C7: Ratio de Fonds propres de base (%) | F7: 0.065 | G7: =+PRUD_01!G10 -> #VALUE!
A8: RA0_002 | B8: 1.2 | C8: Ratio de Fonds propres complémentaires (%) | F8: 0.08 | G8: =PRUD_01!G11 -> #VALUE!
A9: RA0_003 | B9: 1.3 | C9: Ratio de solvabilité total ou de Fonds propres nets (%) | F9: 0.15 | G9: =PRUD_01!G12 -> #VALUE!
A10: RA0_004 | B10: 1.4 | C10: Ratio de solvabilité calculé sur la base des Fonds propres nets corrigés (%) | F10: 0.15 | G10: =PRUD_01!G13 -> #VALUE!
B11: 2 | C11: NORMES DE LIQUIDITE
A12: RA0_005 | B12: 2.1 | C12: Ratio de liquidité immédiate | F12: 0.2 | G12: =PRUD_02!V26 -> 0
A13: RA0_006 | B13: 2.2 | C13: Ratio de couverture des emplois stables par les ressources stables (%) | F13: 1 | G13: =PRUD_03!AF32 -> #DIV/0!
B14: 3 | C14: NORMES DE DIVISION DES RISQUES
A15: RA0_007 | B15: 3.1 | C15: Ratio de division des risques | F15: 0.1 | G15: Nombre de dossiers en infraction(PRUD_04)
A16: RA0_008 | B16: 3.2 | C16: Ratio de limitation des engagements aux mandataires sociaux, dirigeants et salariés | F16: 0.1 | G16: =PRUD_05!W20 -> #VALUE!
A17: RA0_009 | B17: 3.3 | C17: Ratio de diversification | F17: 0.05 | G17: =PRUD_06!Z11 -> #VALUE!
A18: RA0_010 | B18: 3.4 | C18: Ratio de limitation des participations autre que dans les IFI | F18: 0.25 | G18: =PRUD_06!Z15 -> #VALUE!
A19: RA0_011 | B19: 3.5 | C19: Ratio de couverture des Immobilisations | F19: 0.5 | G19: =PRUD_06!Z20 -> #VALUE!
B20: 4 | C20: AUTRES NORMES PRUDENTIELLES
A21: RA0_012 | B21: 4.1 | C21: Ratio de réserve obligatoire | F21: 0.15 | G21: =PRUD_06!Z30 -> #VALUE!
A22: RA0_013 | B22: 4.2 | C22: Ratio de fonds de solidarité financière | F22: 0.05 | G22: =PRUD_06!Z36 -> #VALUE!

Sheet FPNC
B1: CALCUL DES FONDS PROPRES NETS CORRIGES
A6: N°CODE | B6: N° | C6: Poste | D6: Montant (1)
A7: FP0_032 | B7: 1 | C7: Fonds propres Nets (H=C+G Si G<C et C>0 ; H= C+50%C si G>C et C>0; H=C si C<0 ) | D7: FPN/F46
A9: FP0_033 | B9: 2 | C9: Déduction des Dépassements sur les limites réglementaires et gap de provisions sur les créances en souffrance
C10: A dédure des FPN
A11: FP0_034 | B11: 2.1 | C11: Provisions exigées par la BCRG et non encore constituées (*) | D11: FINS_13/AS18 si AS18>0
A12: FP0_035 | B12: 2.2 | C12: Excédent des concours consentis aux actionnaires, administrateurs, dirigeants, salariés et apparentés sur les limites réglementaires (*) | D12: PRUD_05/W21
A13: FP0_036 | B13: 2.3 | C13: Total des Excédents des concours consentis sur une seule signature (*) | D13: PRUD_04/S31
A14: FP0_037 | B14: 2.4 | C14: Excédent des participations dans des entreprises non financières sur les limites réglementaires (*) | D14: PRUD_06 /Z17
A15: FP0_038 | B15: 2.5 | C15: Montant en dépassement de la couverture des Immobilisations sur les limites réglementaires (*) | D15: PRUD_06 /Z27
A16: FP0_039 | B16: 3 | C16: Total I | D16: =SUM(D11:D12) -> 0
A18: FP0_040 | B18: 4 | C18: Fonds propres nets corrigés (N=H-I) | D18: =D7-D16 -> #VALUE!
C19: * Nouveau élément

Sheet FPN
B1: CALCUL DES FONDS PROPRES NETS
C4: (*) Nouveau élément introduit dans le calcul des FPN
A6: N°CODE | B6: N° Compte | C6: Poste | D6: Montant | E6: Pondération | F6: Montant (1)
A7: FP0_000 | C7: 1 Fonds propres de base
C8: A inclure
A9: FP0_001 | B9: 572 | C9: Capital souscrit libéré
A10: FP0_002 | B10: 55 | C10: Réserve générale
A11: FP0_003 | B11: 54 | C11: Réserves facultatives
A12: FP0_004 | B12: 520 | C12: Report à nouveau créditeur
A13: FP0_005 | B13: 592 | C13: 15% des bénéfices du dernier exercice clos, certifiés par le CAC, dans l'attente de son affectation | E13: 0.15 | F13: =+D13*E13 -> 0
A14: FP0_006 | B14: 50 | C14: Provisions du passif (Fonds pour risques bancaires généraux)
A15: FP0_007 | B15: 56 | C15: Fonds de dotation impartageable, à caractère de réserve
A16: FP0_008 | B16: 58 | C16: Fonds de sécurité des réseaux
A17: FP0_009 | C17: Total A | F17: =SUM(F9:F14) -> 0
C18: A déduire
A19: FP0_010 | C19: Actions propres détenues, évaluées à leur valeur comptable | D19: IGEC_18: AT13
A20: FP0_011 | B20: 521 | C20: Report à nouveau débiteur
A21: FP0_012 | B21: 592 | C21: Perte ou déficit d'exercice en instance d’approbation ou d’affectation
A22: FP0_013 | B22: 591 | C22: Résultat déficitaire intermédiaire (*)
A23: FP0_014 | B23: 42 | C23: Actifs incorporels/ immobilisations incorporelles
A24: FP0_015 | B24: 401 | C24: Participations sous forme de fonds propres de base dans des ét. de crédit/fin/Toute participation dans une Institution Financière régulée
A25: FP0_016 | C25: Provisions complémentaires à constituer pour dépréciation ou risque de non recouvrement d'actifs, ou pour charges et pertes diverses | D25: IGEC_18: AT14
A26: FP0_017 | B26: 353 | C26: Dividendes à payer (8)
A27: FP0_018 | C27: Total B | F27: =SUM(F19:F25) -> 0
A29: FP0_019 | C29: Fonds propres de base (C=A-B) | F29: =+F17-F27 -> 0
A30: FP0_020 | C30: 2 Fonds propres complémentaires
C31: A inclure
A32: FP0_021 | C32: 2.1 Instruments de fonds propres complémentaires | F32: =+F33+F34+F35+F36 -> 0
A33: FP0_022 | C33: Réserves de réévaluation certifiées par le commissaire aux comptes | D33: IGEC_18: AT15
A34: FP0_023 | B34: 342 | C34: Comptes bloqués d’associés
A35: FP0_024 | B35: 51 | C35: Subventions d’investissement amortissables au rythme des immobilisations financières
A36: FP0_025 | B36: 53 | C36: Dettes bancaires subordonnées à durée inderminée ou terme >= 5 ans
A37: FP0_026 | C37: 2.2 Primes liées aux instruments de fonds propres additionnels | D37: IGEC_18: AT16
A38: FP0_027 | C38: Total E | F38: =F32+F37 -> 0
C39: A déduire
A40: FP0_028 | B40: 403 | C40: Autres titres immobilisés à valeur de fonds propres (dette subordonnée, prêts participatifs ...) dans des institutions financières agréées
A41: FP0_029 | C41: Comptes courants d’associés bloqués dans d’autres institutions financières | D41: IGEC_18: AT17
A42: FP0_030 | C42: Total F | F42: =SUM(F41:F41) -> 0
A44: FP0_031 | C44: Fonds propres complémentaires (G=E-F) | F44: =+F38-F42 -> 0
A46: FP0_032 | C46: Fonds propres Nets (H=C+G Si G<C et C>0 ; H= C+50%C si G>C et C>0; H=C si C<0 ) | F46: =+F44+F29 -> 0

Sheet APR
A1: RISQUE DE CREDIT : EXPOSITIONS SUR LES ACTIFS
A8: N°CODE | B8: N° Compte | C8: Poste | D8: Exposition nette | E8: Coefficient de pondération | F8: Actifs pondérés des risques
D9: (1) | E9: (2) | F9: (3 )= 1 x 2
A10: RC0_001 | B10: 102 | C10: BCRG | E10: 0 | F10: =+D10*E10 -> 0
A11: RC0_002 | B11: 101 | C11: Caisses | E11: 0.25 | F11: =+D11*E11 -> 0
A12: RC0_003 | B12: 10301 | C12: Placements en banques | E12: 0.25
A13: RC0_004 | B13: 106 | C13: Placements auprès de l'organe faitier (pour le ratio individuel des Institutions affiliées) | E13: 0.25
A14: RC0_005 | B14: 10311 | C14: Placements dans d'autres IFI, hors réseau | E14: 0.5
A15: RC0_006 | B15: 114 | C15: Autres placements financiers | E15: 0.5
A16: RC0_007 | B16: 104 | C16: Autres comptes de disponibilité | E16: 0.5 | F16: =+D16*E16 -> 0
A17: RC0_008 | B17: 105 | C17: Chèques et effets à l'encaissement | E17: 0.25 | F17: =+D17*E17 -> 0 | P17: ,
A18: RC0_009 | C18: Portefeuille de crédit sain à la clientèle, après déduction des dépôts de garantie (gage- espèce) éventuels, pouvant être compensés en cas de non remboursement | D18: =D19-D20 -> 0 | E18: 1 | F18: =+D18*E18 -> 0
A19: RC0_010 | B19: 20 | C19: Crédits sains | F19: 0
A20: RC0_011 | B20: 2430 | C20: Dépôts de garantie financière | F20: 0
A21: RC0_012 | C21: Opérations diverses | D21: COMPTES (30+31+32+33)- COMPTES (390+391+394) | E21: 1 | F21: =+D21*E21 -> #VALUE!
A22: RC0_013 | C22: Toutes créances en souffrance (au secteur financier, à la clientèle, en opérations diverses), pour leur valeur nette | D22: COMPTES (13+21+323)- COMPTES (19+29+393) | E22: 1.5 | F22: =+D22*E22 -> #VALUE!
A23: RC0_014 | C23: Immobilisations nettes, après déduction des éléments retirés des fonds propres | D23: COMPTES (40+41+43+44)- COMPTES (48+401) | E23: 1 | F23: =+D23*E23 -> #VALUE!
A24: RC0_015 | B24: 90 | C24: les engagementrs de financement et garanties octroyés figurant au hors bilan | E24: 1 | F24: =+D24*E24 -> 0
A25: RC0_016 | C25: TOTAL | D25: =SUM(D10:D24) -> 0 | F25: =SUM(F10:F24) -> #VALUE!

Sheet PRUD_01
C1: CALCUL DES RATIOS DE SOLVABILITE
A8: N°CODE | B8: N° | C8: Poste | F8: Référence | G8: Niveau /Montant estimé (1)
B9: 1 | C9: Normes de solvabilité
A10: RA0_001 | B10: 1.1 | C10: Fonds propres de base | F10: a x 100 / e | G10: =+G15/G20 -> #VALUE!
A11: RA0_002 | B11: 1.2 | C11: Fonds propres Complémentaires | F11: b x 100 / e | G11: =+G16/G20 -> #VALUE!
A12: RA0_003 | B12: 1.3 | C12: Fonds propres nets | F12: cx 100 / e | G12: =+G17/G20 -> #VALUE!
A13: RA0_004 | B13: 1.4 | C13: Fonds propres nets corrigés | F13: dx 100 / e | G13: =+G18/G20 -> #VALUE!
B14: 2 | C14: Fonds propres
A15: FP0_019 | B15: 2.1 | C15: Fonds propres de base | F15: FPN_F29 | G15: =+FPN!F29 -> 0 | H15: (a)
A16: FP0_031 | B16: 2.2 | C16: Fonds propres complémentaires | F16: FPN_F44 | G16: =FPN!F44 -> 0 | H16: (b)
A17: FP0_032 | B17: 2.3 | C17: Fonds propres nets | F17: FPN_F46 | G17: =FPN!F46 -> 0 | H17: (c)
A18: FP0_040 | B18: 2.4 | C18: Fonds propres nets Corrigés | F18: FPNC_D18 | G18: =+FPNC!D18 -> #VALUE! | H18: (d)
B19: 3 | C19: Actifs pondérés des risques (APR)
A20: APR_04 | B20: 3.1 | C20: Actifs pondérés des risques de crédit, de marché et opérationel | F20: APR | G20: =+APR!F25 -> #VALUE! | H20: (e)

Sheet PRUD_02
B1: COEFFICIENT D'OBSERVATION DE LIQUIDITE IMMEDIATE
B2: PRUD_02
B4: PAYS: | M4: INSTITUTION :
E6: A | F6: A | G6: A | H6: M | I6: M | J6: J | K6: J | Y6: A
R7: CIB | V7: LC
A9: N°CODE | B9: N° compte | E9: Numérateur - Réalisables | V9: Encours bruts
V10: GNF
V11: 1
A12: EPR_0800 | E12: 1. ELEMENTS DU BILAN REALISABLES | V12: =+SUM(V13:Y18) -> 0
A13: EPR_0810 | B13: 101 | E13: 1.1. Avoir en Caisse
A14: EPR_0820 | B14: 102 | E14: 1.2. BCRG comptes ordinaires
A15: EPR_0830 | B15: 103 | E15: 1.3. Comptes ordinaires auprès des banques et institutions financières
A16: EPR_0840 | B16: 104 | E16: 1.3. Autres comptes de disponibilité
A17: EPR_0850 | B17: 105 | C17: 105 | E17: 1.3. Chèques et effets à l'encaissement
A18: EPR_0860 | B18: 106 | E18: 1.3. Organe faitier/ Caisse centrale de réseau
A20: N° CODE | E20: Dénominateur : Exigibles | V20: Encours bruts
V21: GNF
V22: 1
A23: EPR_0870 | E23: 2. ELEMENTS DU BILAN EXIGIBLES
A24: EPR_0880 | B24: 241 | E24: 2.1 Comptes de dépôts à Vue
A25: EPR_0890 | E25: 3. TOTAL EXIGIBLES | V25: =V23 -> 0
A26: EPR_0900 | E26: 4. RATIO DE LIQUIDITE IMMEDIATE = 1/3

Sheet PRUD_03
A1: COUVERTURE DES EMPLOIS STABLES PAR LES RESSOURCES STABLES /COEFFICIENT DE TRANSFORMATIONS DE PLUS D' UN (1) AN DES IMF
A2: PRUD_03
B4: PAYS: | K4: INSTITUTION :
A6: A | C6: A | D6: A | E6: A | F6: A | G6: A | H6: M | I6: M | J6: J | K6: J | W6: A | X6: A | AF6: 0 | AG6: 7 | AH6: M
A7: Date d'arrêté | P7: CIB | T7: LC | X7: D | AF7: F | AH7: P | AK7: CM
A9: N° CODE | B9: N° Compte | C9: Composition | AF9: Montant
A10: EPR_1320 | C10: 1.NUMERATEUR (N) | AF10: =AF11 -> 0
A11: EPR_0010 | C11: 1.1. RESSOURCES STABLES (échéance > 1 AN) | AF11: =+SUM(AF12:AK27) -> 0
A12: EPR_0020 | B12: 171 et 172 | C12: 1.1.1. Emprunts à moyen et long terme auprès du secteur financier ( dettes rattachées) (Échéance supérieure à 1 an) | AF12: FINS_16/X13+AC13
A13: EPR_0030 | C13: 1.1.2. Ressources affectées (échéance supérieure à 1an) | AF13: FINS_16/X16+AC16
A14: EPR_0040 | C14: 1.1.2. Produits d'épargne (échéance supérieure à 1an) | AF14: FINS_16/X17+AC17
A15: EPR_0050 | C15: 1.1.4. Quote-part des dépôts de garantie bloqués, couvrant des crédits MLT | AF15: FINS_16/X18+AC18
A16: EPR_0060 | C16: 1.1.3. Quote-part des dépôts à Terme (> 1an) | AF16: FINS_16/X19+AC19
A17: EPR_0070 | C17: 1.1.4. Quote-part Autres dépôts (échéance supérieure à 1an) | AF17: FINS_16/X20+AC20
A18: EPR_0080 | B18: 50 | C18: 1.1.5. Provisions du passif | AF18: N° Compte50
A19: EPR_0130 | B19: 51 | C19: 1.2.1. Subvension d'investissement | AF19: N° Compte 51
A20: EPR_0140 | B20: 52 | C20: 1.2.2. Report à nouveau | AF20: N° Compte 52
A21: EPR_0150 | B21: 53 | C21: 1.2.3. Dettes subordonnées & assimilées exigibles aux fonds propres | AF21: N° Compte 53
A22: EPR_0160 | B22: 54 | C22: 1.2.4. Réserves facultatives | AF22: N° Compte 54
A23: EPR_0170 | B23: 55 | C23: 1.2.5. Réserves générales | AF23: N° Compte 55
A24: EPR_0230 | B24: 56 | C24: 1.2.6. Fonds de dotation impartageable, à caractère de réserve | AF24: N° Compte 56
A25: EPR_0260 | B25: 572 | C25: 1.4.1. Capital social libéré | AF25: N° Compte 572
A26: EPR_0270 | B26: 58 | C26: 1.4.2. Fonds de solidarité financière des réseaux | AF26: N° Compte 58
A27: EPR_0280 | B27: 59 | C27: 1.4.3. 15% exécedent ou 100% de pertes | AF27: N° Compte 59
A28: EPR_1330 | C28: 2. DENOMINATEUR (D) | AF28: =SUM(AF29:AK31) -> 0
A29: EPR_1340 | C29: 2.1. Immobilisations nettes | AF29: COMPTES (40+41+42+43+44)-COMPTE 48
A30: EPR_1380 | B30: 21 | C30: 2.2. Créances en souffrance | AF30: COMPTE 21
A31: EPR_1400 | C31: 2.3. Crédits sains à la clientèle (fraction ayant plus de 1 an à courir) (VOIR BALANCE AGEE DES CREDITS SAINS DANS FINS_18) | AF31: FINS_16/X21+AC21
A32: EPR_1420 | C32: 3. COEFFICIENT DE TRANSFORMATION =(Numératuer / Dénominateur) | AF32: =AF10/AF28 -> #DIV/0!

Sheet PRUD_04
A1: DIVISION DES RISQUES
A2: PRUD_04
B4: PAYS: | N4: INSTITUTION
D6: A | E6: A | F6: A | G6: A | H6: M | I6: M | J6: J | K6: J
D7: Date d'arrêté | O7: LC
A8: Pour mémoire
A9: Indicateur | F9: Fonds propres nets | N9: FPN-F46
A11: 10% des FPN | N11: =10%*N9 -> #VALUE!
A12: 8 fois les FPN
A13: N° CODE | B13: N° | D13: Nom ou Raison Sociale du Bénéficiaire (Liste IGEC2) | N13: Exposinettes nettes ou Risque par bénéficiaire | R13: Norme par Bénéficiaire | S13: Ecart sur les engagements individuels depassant 10% des FPN
N16: 1 | R16: 2=1/N9 | S16: 3=1-N11
A17: EPR_0110 | B17: 1
A18: EPR_0120 | B18: 2
A19: EPR_0130 | B19: 3
A20: EPR_0140 | B20: 4
A21: EPR_0150 | B21: 5
A22: EPR_0160 | B22: 6
A23: EPR_0170 | B23: 7
A24: EPR_0180 | B24: 8
A25: EPR_0190 | B25: 9
A26: EPR_0200 | B26: 10
A27: EPR_0210 | B27: 11
A28: EPR_0220 | B28: 12
A29: EPR_0230 | B29: 13
A30: TT0_0270 | B30: 14 | D30: TOTAL DES ENGAGEMENTS BRUTS | N30: =SUM(N17:Q29) -> 0 | S30: =SUM(S17:U29) -> 0
A31: TE0_0270 | B31: 15 | D31: TOTAL DES ECARTS SUR LES NGAGEMENTS DEPASSANT INDIVIDUELLEMENT 10% DES FPN | S31: =S30 -> 0

Sheet PRUD_05
B1: CONCOURS CONSENTIS AUX MANDATAIRES SOCIAUX, DIRIGEANTS SALARIES
B2: PRUD_05
C4: PAYS: | M4: INSTITUTION :
D6: A | E6: A | F6: A | G6: A | H6: A | I6: M | J6: M | K6: J | L6: J | W6: 0 | X6: 7
D7: Date d'arrêté | R7: CIB | W7: F
B9: INDICATEUR
H11: Fonds propres nets (FPN) | R11: FPN_F46
H13: 10% des FPN | R13: =R11*10% -> #VALUE!
A14: N°CODE | B14: N° | C14: Nom ou raison sociale du bénéficiaire | M14: Montant des concours* | R14: Provisions comptabilisées | W14: Montant Net des Concours accordés
M16: 1 | R16: 2 | W16: 3 = 1- 2
A17: EPR_0600 | B17: 1 | M17: IGEC17_AE17 | R17: IGEC17_AO17
A18: EPR_1000 | B18: 2 | C18: TOTAL DES ENGAGEMENTS AUX SALARIES | M18: IGEC16_AF17 | R18: IGEC16_AM17
A19: TT0_0280 | B19: 3 | C19: TOTAL | M19: =+M17+M18 -> #VALUE! | R19: =+R17+R18 -> #VALUE! | W19: =+W17+W18 -> 0
A20: TS0_0290 | B20: 4 | C20: SEUIL | W20: =+W19/R11 -> #VALUE!
A21: TD0_0300 | B21: 5 | C21: Montant total des dépassements | W21: Si W19>R13 ; W19-R13 ; 0
C22: *Prêts, crédits, avances, effets escomptés, comptes ordinaires débiteurs, y compris les crédits garantis par nantissement de marchés publics ou de produits à l'exportation

Sheet PRUD_06
A1: AUTRES NORMES PRUDENTIELLES
A2: PRUD_06
A4: PAYS | M4: INSTITUTION :
D6: A | E6: A | F6: A | G6: M | H6: M | I6: J | J6: J | V6: 0 | W6: 7 | AB6: M
Q7: CIB | V7: F | AB7: P | AF7: CM
A9: N° CODE | B9: N° | D9: AUTRES NORMES PRUDENTIELLES | T9: Montant | Z9: Seuil observé | AF9: Norme
B10: 1 | D10: RATIO DE DIVERSIFICATION
A11: EPR_1510 | B11: 1.1 | D11: Produits non bancaires (I) | T11: FINS_09/AC32 | Z11: =T11/T12 -> #VALUE! | AF11: ≤ 5%
A12: EPR_1520 | B12: 1.2 | D12: Total des Produits (II) | T12: FINS_09/AC12
B14: 2 | D14: RATIO DE LIMITATION DES PARTICIPATIONS AUTRES QUE DANS LES INSTITUTIONS FINANCIERES
A15: EPR_1530 | B15: 2.2 | D15: Autres titres de participation (I) | T15: COMPTE 402 | Z15: =+T15/T16 -> #VALUE! | AF15: ≤ 25%
A16: EPR_1540 | B16: 2.3 | D16: Fonds propres nets (II) | T16: FPN_F46
A17: EPR_1550 | B17: 2.4 | D17: Calcul du montant en dépassement (III) | T17: 25%FPN_F46 | Z17: Si T15>T17; T15-T17; 0
B19: 3 | D19: RATIO DE COUVERTURE DES IMMOBILISATIONS PAR LES FONDS PROPRES
A20: EPR_1560 | B20: 3.1 | D20: Total des Immobilisations (I) | T20: =T21+T22+T23+T24+T25 -> #VALUE! | Z20: =T20/T26 -> #VALUE! | AF20: ≤ 50%
A21: EPR_1570 | B21: 3.1.1 | D21: Autres titres de participations | T21: COMPTE 402
A22: EPR_1580 | B22: 3.1.2. | D22: Autres titres immobilisés hors Institutions Financières | T22: COMPTE 404
A23: EPR_1590 | B23: 3.1.3 | D23: Dépôts et cautionnements (MLT) | T23: COMPTE 411
A24: EPR_1600 | B24: 3.1.4. | D24: Immobilisations corporelles | T24: COMPTE 43
A25: EPR_1610 | B25: 3.1.5. | D25: Immobilisations en cours | T25: COMPTE 44
A26: EPR_1620 | B26: 3.2 | D26: Fonds propres nets (II) | T26: FPN_F46
A27: EPR_1630 | B27: 3.3 | D27: Calcul du montant en dépassement0% Fonds propres nets (III) | T27: 50%FPN_F46 | Z27: Si T20>T27; T20-T27; 0
B29: 4 | D29: RATIO DE RESERVE LEGALE OBLIGATOIRE
A30: EPR_1640 | B30: 4.1 | D30: Bénéfice de l'exercice | T30: IGEC_18: AT20 | Z30: =T31/T30 -> #VALUE! | AF30: ≥ 15%
A31: EPR_1650 | B31: 4.2 | D31: Variation poste réserve légale obligatoire | T31: =T32-T33 -> #VALUE!
A32: EPR_1660 | B32: 4.2.1 | D32: Réserves légales oblogatoire (exercice N) | T32: IGEC_18: AT18
A33: EPR_1670 | B33: 4.2.2 | D33: Réserves légales oblogatoire (exercice N-1) | T33: IGEC_18: AT19
B35: 5 | D35: RATIO FONDS DE SOLIDARITE FINANCIERE **
A36: EPR_1680 | B36: 5.1 | D36: Fonds de solidarité financière | T36: COMPTE 58 | Z36: =T36/T37 -> #VALUE! | AF36: ≥ 5%
A37: EPR_1690 | B37: 5.2 | D37: Actif net | T37: SITU_01/AK63
A38: *EP: Etat Périodique | D38: ** NORME RELATIVE A LA FAITIERE DES INSTITUTIONS COOPERATIVES ORGANISEES EN RESEAU

Sheet IMAO_ICD
B1: IMF collectant de dépôt
B2: IMAO_ICD
C4: PAYS: | M4: INSTITUTION :
E6: A | F6: A | G6: A | H6: A | I6: M | J6: M | K6: J | L6: J | W6: 0 | X6: 7 | AC6: M
R7: CIB | W7: F | AC7: P | AG7: CM
A9: N°CODE | B9: N° | E9: RATIOS PRUDENTIELS HARMONISES | U9: Montant | AA9: Seuil observé | AG9: Norme
A10: ICD_001 | B10: 1 | E10: ADEQUATION DES FONDS PROPRES (ADFPN)
A11: ICD_002 | B11: 1.1 | E11: Capital réglementaire (Tier 1+ Tier 2) (I) | U11: FPN_F56 | AA11: =U11/U12 -> #VALUE! | AG11: ≥10%
A12: ICD_003 | B12: 1.2 | E12: Total des actifs pondérés en fonction des risques (II) | U12: APR_F25
A13: ICD_004 | B13: 2 | E13: QUALITE DES ACTIFS (QDA)
A14: ICD_005 | B14: 2.1 | E14: Ratio qualité des actifs 1 (RQA1)
A15: ICD_006 | B15: 2.1.1 | E15: Créances en souffrance | U15: SOLDE COMPTE 21 | AA15: =+U15/U16 -> #VALUE! | AG15: ≤ 10%
A16: ICD_007 | B16: 2.1.2 | E16: Total des prêts bruts | U16: SOLDE COMPTE (20+21-208)
A17: ICD_008 | B17: 2.2 | E17: Ratio qualité des actifs 2 (RQA2)
A18: ICD_009 | B18: 2.2.1 | E18: Provisions | U18: SOLDE COMPTE 29 | AA18: =U18/U19 -> #VALUE!
A19: ICD_010 | B19: 2.2.2 | E19: Créances en souffrance | U19: SOLDE COMPTE 21
A20: ICD_011 | B20: 3 | E20: GAIN ET RENTABILITE (GER)
A21: ICD_012 | B21: 3.1 | E21: Ratio bénéfice net avant impôts / Total actif moyen (RBNAI/TAM)
A22: ICD_013 | B22: 3.1.1 | E22: Bénéfice net avant impôts | U22: FINS_10 : AA141 | AA22: =U22/U23 -> #VALUE! | AG22: > 0%
A23: ICD_014 | B23: 3.1.2 | E23: Total Actif moyen | U23: MOYENNE DES ACTIFS MEME EXERCICE
A24: ICD_015 | B24: 3.2 | E24: Ratio revenu net après impôts/ Total des fonds propres moyens (RRNAI/TFPM)
A25: ICD_016 | B25: 3.2.1 | E25: Revenu net après impôts (I) | U25: FINS_10: AA143 | AA25: =U25/U26 -> #VALUE! | AG25: > 0%
A26: ICD_017 | B26: 3.2.2 | E26: Total des fonds propres moyens (II) | U26: MOYENNE FPN MEME EXERCICE
A27: ICD_018 | B27: 3.3 | E27: Ratio revenu net d'intérêt/Revenu brut (RRNI/RB)
A28: ICD_019 | B28: 3.3.1 | E28: Revenu net d'intérêt (I) | U28: FINS_09 : AC12-AC62 | AA28: =U28/U29 -> #VALUE!
A29: ICD_020 | B29: 3.3.2 | E29: Revenu brut (II) | U29: FINS_09 : AC12
A30: ICD_021 | B30: 4 | E30: LIQUIDITE
A31: ICD_022 | B31: 4.1 | E31: Ratio de liquidité des actifs (RDLA)
A32: ICD_023 | B32: 4.1.1 | E32: Actifs liquides | U32: SITU_01/AK12 | AA32: =U32/U33 -> #VALUE!
A33: ICD_024 | B33: 4.1.2 | E33: Total Actif | U33: SITU_01/AK63
A34: ICD_025 | B34: 4.2 | E34: Ratio liquidité moins d'un an (RLM1AN)
A35: ICD_026 | B35: 4.2.1 | E35: Actifs liquides (I) | U35: SITU_01/AK12 | AA35: =U35/U36 -> #VALUE!
A36: ICD_027 | B36: 4.2.2 | E36: Total passif à CT (moins d'un 1 an) | U36: SITU_02/AD63- PRUD_03/AK11
A37: ICD_028 | B37: 4.3 | E37: Ratio liquidité sur total dépôt (RLSTD)
A38: ICD_029 | B38: 4.3.1 | E38: Actifs liquides (I) | U38: SITU_01/AK12 | AA38: =U38/U39 -> #VALUE!
A39: ICD_030 | B39: 4.3.2 | E39: Total dépôt (II) | U39: COMPTES (24+25)- COMPTE (248+258)
A40: ICD_031 | B40: 5 | E40: GRAND RISQUE & CONCENTRATION
A41: ICD_032 | B41: 5.1 | E41: Ratio total des prêts / Total dépôt (RTDP/TD)
A42: ICD_033 | B42: 5.1.1 | E42: Total des prêts | U42: COMPTES (20+21)- COMPTE 208 | AA42: =U42/U43 -> #VALUE! | AG42: < 80%
A43: ICD_034 | B43: 5.1.2 | E43: Total dépôt | U43: COMPTES (24+25)- COMPTE (248+258)
...

Sheet IMAO_INCD
B1: IMF ne collectant pas de dépôt
B2: IMAO_INCD
C4: PAYS: | M4: INSTITUTION :
D6: A | E6: A | F6: A | G6: A | H6: A | I6: M | J6: M | K6: J | L6: J | W6: 0 | X6: 7 | AC6: M
D7: Date d'arrêté | R7: CIB | W7: F | AC7: P | AG7: CM
A9: N° CODE | B9: N° | E9: RATIOS PRUDENTIELS HARMONISES | U9: Montant | AA9: Seuil observé | AG9: Norme
A10: INCD_001 | B10: 1 | E10: ADEQUATION DES FONDS PROPRES
A11: INCD_002 | B11: 1.1 | E11: Capital réglementaire (Tier 1+ Tier 2) (I) | U11: FPN_F56 | AA11: =U11/U12 -> #VALUE! | AG11: ≥10%
A12: INCD_003 | B12: 1.2 | E12: Total des actifs pondérés en fonction des risques (II) | U12: APR_F25
A13: INCD_004 | B13: 2 | E13: QUALITE DES ACTIFS
A14: INCD_005 | B14: 2.1 | E14: Ratio qualité des actifs 1
A15: INCD_006 | B15: 2.1.1 | E15: Créances en souffrance | U15: SOLDE COMPTE 21 | AA15: =+U15/U16 -> #VALUE! | AG15: ≤ 10%
A16: INCD_007 | B16: 2.1.2 | E16: Total des prêts bruts | U16: SOLDE COMPTE (20+21-208)
A17: INCD_008 | B17: 2.2 | E17: Ratio qualité des actifs 2
A18: INCD_009 | B18: 2.2.1 | E18: Provisions | U18: SOLDE COMPTE 29 | AA18: =U18/U19 -> #VALUE!
A19: INCD_010 | B19: 2.2.2 | E19: Créances en souffrance | U19: SOLDE COMPTE 21
A20: INCD_011 | B20: 3 | E20: GAIN ET RENTABILITE
A21: INCD_012 | B21: 3.1 | E21: Ratio bénéfice net avant impôts / Total actif moyen
A22: INCD_013 | B22: 3.1.1 | E22: Bénéfice net avant impôts | U22: FINS_10:AA141 | AA22: =U22/U23 -> #VALUE! | AG22: > 0%
A23: INCD_014 | B23: 3.1.2 | E23: Total Actif moyen | U23: MOYENNE DES ACTIFS MEME EXERCICE
A24: INCD_015 | B24: 3.2 | E24: Ratio revenu net après impôts/ Total des fonds propres moyens
A25: INCD_016 | B25: 3.2.1 | E25: Revenu net après impôts (I) | U25: FINS_10:AA143 | AA25: =U25/U26 -> #VALUE! | AG25: > 0%
A26: INCD_017 | B26: 3.2.2 | E26: Total des fonds propres moyens (II) | U26: MOYENNE FPN MEME EXERCICE
A27: INCD_018 | B27: 3.3 | E27: Ratio revenu net d'intérêt/Revenu brut
A28: INCD_019 | B28: 3.3.1 | E28: Revenu net d'intérêt (I) | U28: FINS_09 : AC12-AC62 | AA28: =U28/U29 -> #VALUE!
A29: INCD_020 | B29: 3.3.2 | E29: Revenu brut (II) | U29: FINS_09 : AC12
A30: INCD_021 | B30: 4 | E30: LIQUIDITE
A31: INCD_022 | B31: 4.1 | E31: Ratio de liquidité des actifs
A32: INCD_023 | B32: 4.1.1 | E32: Actifs liquides | U32: SITU_01/AK12 | AA32: =U32/U33 -> #VALUE!
A33: INCD_024 | B33: 4.1.2 | E33: Total Actif | U33: SITU_01/AK63
A34: INCD_025 | B34: 4.2 | E34: RatIo de liquidité de moins d'un an
A35: INCD_026 | B35: 4.2.1 | E35: Actifs liquides (I) | U35: SITU_01/AK12 | AA35: =U35/U36 -> #VALUE!
A36: INCD_027 | B36: 4.2.2 | E36: Total passif à CT (moins d'un 1 an) | U36: SITU_02/AD63- PRUD_03/AK11
A37: INCD_028 | B37: 5 | E37: GRAND RISQUE & CONCENTRATION
A38: INCD_029 | B38: 5.1 | E38: Ratio total des prêts / passif à CT
A39: INCD_030 | B39: 5.1.1 | E39: Total des prêts | U39: COMPTES (20+21)- COMPTE 208 | AA39: =U39/U40 -> #VALUE! | AG39: < 80%
A40: INCD_031 | B40: 5.1.2 | E40: Passif à CT | U40: SITU_02/AD63- PRUD_03/AK11
A41: INCD_032 | B41: 5.2 | E41: Ratio prêts au secteur économique/ Prêts bruts
A42: INCD_033 | B42: 5.2.1 | E42: Prêts au secteur économique | U42: FINS_03: AM23-AM22 | AA42: =U42/U43 -> #VALUE!
A43: INCD_034 | B43: 5.2.2 | E43: Prêts bruts | U43: COMPTES (20+21)- COMPTE 208
...
