Workbook

Sheet M.0.INFO.G
B1: Nom de l'institution | C1: YETEMALI
B2: Code de l'institution | C2: 001
B3: Date des rapports | C3: 31/03/2019
B4: Rapport | C4: M.0.INFORMATION GENERALE
A6: CODE | B6: INFORMATION | C6: DONNEES
A7: M.0.LS | B7: Statut légal | C7: SA
A8: M.0.LD | B8: Date d'agrément | C8: 01/05/23
A9: M.0.MLO | B9: Adresse du siège | C9: Kipé ( En face de la Station Total et à côté du Lycée français)
A10: M.0.MLO.1 | B10: Ville | C10: Conakry
A11: M.0.MLO.2 | B11: Commune | C11: Ratoma
A12: M.0.MLO.3 | B12: Quartier | C12: Kipé/Kaporo
A13: M.0.TL | B13: Numéro de téléphone | C13: 657 66 60 00/628 00 88 04
A14: M.0.EM | B14: Email | C14: cpecg@yetemali-gn.com
A15: M.0.MD | B15: Nom du Directeur Général/Responsable | C15: MAGASSOUBA Diamadi
C18: CONTROLE DE COHERENCE
A19: 1 | B19: =IF(M.I.BILAN!F76=M.I.BILAN!F149,"ok","erreur") | C19: Actif = Passif
A20: 2 | B20: =IF(M.II.RESULTAT!D58=M.II.RESULTAT!D105,"ok","erreur") | C20: Charge = Produit
A21: 3 | B21: =IF(M.I.BILAN!E33>=ABS(M.II.RESULTAT!D46-M.II.RESULTAT!D95),"ok","erreur") | C21: Provisions sur le bilan et sur le compte de résultat
A22: 4 | B22: =IF(M.I.BILAN!F148=M.II.RESULTAT!D57-M.II.RESULTAT!D104,"ok","erreur") | C22: Résultat sur le Bilan et sur le Compte de résultat
A23: 5 | B23: =IF(M.I.BILAN!D33-M.I.BILAN!D40=M.IV.IMPAYE!E14-M.IV.IMPAYE!E13,"ok","erreur") | C23: Encours Bilan et Impayé
A24: 6 | B24: =IF(M.I.BILAN!F106>=M.IV.IMPAYE!G14,"ok","erreur") | C24: Dépôt de garantie Bilan et Impayé
A25: 7 | B25: =IF(M.I.BILAN!D41>=M.IV.IMPAYE!C22-M.IV.IMPAYE!E13,"ok","erreur") | C25: Encours en souffrance Bilan et Impayé
A26: 8 | B26: =IF(M.I.BILAN!F34-M.I.BILAN!F40=M.IV.IMPAYE!E7,"ok","erreur") | C26: Encours sain Bilan et Impayé
A27: 9 | B27: =IF(M.I.BILAN!D33-M.I.BILAN!F40=M.XI.RPCS!I12,"ok","erreur") | C27: Encours crédit Bilan et Répartition par secteur
A28: 10 | B28: =IF(M.V.PFC!C7=M.XV.RECAP!D28,"ok","erreur") | C28: Volume crédit et Répartition par Recap (encours secteur d'activité

Sheet M.I.BILAN
B1: Nom de l'institution | D1: ='M.0.INFO.G'!C1
B2: Code de l'institution | D2: ='M.0.INFO.G'!C2
B3: Date des rapports | D3: ='M.0.INFO.G'!C3
B4: Rapport | D4: M.I.BILAN
A6: CODE | B6: N° compte | C6: ACTIF | D6: Montant brut | E6: Amortissement & Provisions | F6: Montant net
A7: M.I.B.A.1 | B7: 1 | C7: OPERATIONS AVEC LE SECTEUR FINACIER | D7: =+D8+D16 | F7: =D7-E7
A8: M.I.B.A.10 | B8: 10 | C8: Encaisses et comptes ordinaires | D8: =SUM(D9:D15) | F8: =D8-E8
A9: M.I.B.A.101 | B9: 101 | C9: Caisses | F9: =D9-E9
A10: M.I.B.A.102 | B10: 102 | C10: Banque Centrale | F10: =D10-E10
A11: M.I.B.A.103 | B11: 103 | C11: Banques et institutions financières | F11: =D11-E11
A12: M.I.B.A.104 | B12: 104 | C12: Autres comptes de disponibilités (compte de DAT) | F12: =D12-E12
A13: M.I.B.A.105 | B13: 105 | C13: Chèques et effets à l'encaissement | F13: =D13-E13
A14: M.I.B.A.106 | B14: 106 | C14: Organe faîtier/ Caisse Centrale de réseau | F14: =D14-E14
A15: M.I.B.A.108 | B15: 108 | C15: Créances rattachées | F15: =D15-E15
A16: M.I.B.A.11 | B16: 11 | C16: Prêts et titres à court terme ( 0-2ans) | D16: =D17+D20+D23+D26+D27 | F16: =D16-E16
A17: M.I.B.A.111 | B17: 111 | C17: Banque Centrale | D17: =D18+D19 | F17: =D17-E17
A18: M.I.B.A.1111 | B18: 1111 | C18: Très court terme | F18: =D18-E18
A19: M.I.B.A.1112 | B19: 1112 | C19: Autres court terme | F19: =D19-E19
A20: M.I.B.A.112 | B20: 112 | C20: Banques et institutions financières | D20: =D21+D22 | F20: =D20-E20
A21: M.I.B.A.1121 | B21: 1121 | C21: Très court terme | F21: =D21-E21
A22: M.I.B.A.1122 | B22: 1122 | C22: Autres court terme | F22: =D22-E22
A23: M.I.B.A.113 | B23: 113 | C23: Autres secteur financier | D23: =D24+D25 | F23: =D23-E23
A24: M.I.B.A.1131 | B24: 1131 | C24: Très court terme (obligations, TCN, …) | F24: =D24-E24
A25: M.I.B.A.1132 | B25: 1132 | C25: Autres court terme | F25: =D25-E25
A26: M.I.B.A.114 | B26: 114 | C26: Bons du Trésor et Autres titre émis par une entité publique | F26: =D26-E26
A27: M.I.B.A.118 | B27: 118 | C27: Créances rattachées ( intérêts courus non échus) | F27: =D27-E27
A28: M.I.B.A.12 | B28: 12 | C28: Prêts à moyen et long terme ( 2 ans et +) | D28: =D29+D30+D31+D32 | F28: =D28-E28
A29: M.I.B.A.122 | B29: 122 | C29: Banques et institutions financières | F29: =D29-E29
A30: M.I.B.A.123 | B30: 123 | C30: Autres secteur financier | F30: =D30-E30
A31: M.I.B.A.124 | B31: 124 | C31: Bons du Trésor et Autres titre émis par une entité publique | F31: =D31-E31
A32: M.I.B.A.128 | B32: 128 | C32: Créances rattachées ( intérêts courus non échus) | F32: =D32-E32
A33: M.I.B.A.2 | B33: 2 | C33: OPERATIONS AVEC LA CLIENTELE | D33: =D34+D41 | E33: =+E41 | F33: =D33-E33
A34: M.I.B.A.20 | B34: 20 | C34: Crédit sains ( selon la durée initiale) | D34: =D35+D38+D39+D40 | F34: =D34-E34
A35: M.I.B.A.201 | B35: 201 | C35: Court terme ( 0-2ans) | D35: =D36+D37 | F35: =D35-E35
A36: M.I.B.A.2011 | B36: 2011 | C36: Très court terme ( 0-3mois) | F36: =D36-E36
A37: M.I.B.A.2012 | B37: 2012 | C37: Autres court terme ( +3mois à 2ans) | F37: =D37-E37
A38: M.I.B.A.202 | B38: 202 | C38: Moyen terme ( +2 à 5 ans) | F38: =D38-E38
A39: M.I.B.A.203 | B39: 203 | C39: Long terme (plus de 5 ans) | F39: =D39-E39
A40: M.I.B.A.208 | B40: 208 | C40: Créances rattachées ( intérêts courus non échus) | F40: =D40-E40
A41: M.I.B.A.21 | B41: 21 | C41: Créances en souffrance | D41: =D42+D43+D44+D45 | E41: =SUM(E42:E45) | F41: =D41-E41
...

Sheet M.II.RESULTAT
B1: Nom de l'institution | D1: ='M.0.INFO.G'!C1
B2: Code de l'institution | D2: ='M.0.INFO.G'!C2
B3: Date des rapports | D3: ='M.0.INFO.G'!C3
B4: Rapport | D4: M.II.COMPTE DE RESULTAT
A6: CODE | B6: N° compte | C6: CHARGES | D6: Montant
A7: M.II.R.C.6 | B7: 6 | C7: OPERATIONS DE CHARGES | D7: =D8+D18+D26+D33+D37+D40+D44+D52+D55
A8: M.II.R.C.60 | B8: 60 | C8: CHARGES FINANCIERES | D8: =D9+D15
A9: M.II.R.C.601 | B9: 601 | C9: Intérêts | D9: =D10+D11+D12+D13+D14
A10: M.II.R.C.6011 | B10: 6011 | C10: Intérêts sur dépôt à vue
A11: M.II.R.C.6012 | B11: 6012 | C11: Intérêts sur dépôts à terme
A12: M.II.R.C.6013 | B12: 6013 | C12: Intérêts sur emprunts à moins d'un an
A13: M.II.R.C.6014 | B13: 6014 | C13: Intérêts sur emprunts à terme
A14: M.II.R.C.6015 | B14: 6015 | C14: Autres intérêts
A15: M.II.R.C.602 | B15: 602 | C15: Autres charges financières | D15: =D16+D17
A16: M.II.R.C.6021 | B16: 6021 | C16: Commissions
A17: M.II.R.C.6022 | B17: 6022 | C17: Charge nette/cession de titres à court terme | D17: 0
A18: M.II.R.C.61 | B18: 61 | C18: ACHATS DE FOURNITURE DE BUREAU | D18: =D19+D22+D23+D24+D25
A19: M.II.R.C.611 | B19: 611 | C19: Achats de fourniture de bureau | D19: =+D20+D21
A20: M.II.R.C.6110 | B20: 6110 | C20: Achats
A21: M.II.R.C.6111 | B21: 6111 | C21: Variations de stock (a)
A22: M.II.R.C.612 | B22: 612 | C22: Eau et électricité
A23: M.II.R.C.613 | B23: 613 | C23: Locations
A24: M.II.R.C.614 | B24: 614 | C24: Entretiens et réparations
A25: M.II.R.C.615 | B25: 615 | C25: Primes d'assurance
A26: M.II.R.C.62 | B26: 62 | C26: AUTRES SERVICES EXTERIEURS | D26: =SUM(D27:D32)
A27: M.II.R.C.621 | B27: 621 | C27: Publicité et rélations publiques
A28: M.II.R.C.622 | B28: 622 | C28: Transports et déplacements
A29: M.II.R.C.623 | B29: 623 | C29: Frais postaux et de télécommunications
A30: M.II.R.C.624 | B30: 624 | C30: Services bancaires
A31: M.II.R.C.625 | B31: 625 | C31: Frais de formation, d'éducation, d'études et de recherche
A32: M.II.R.C.626 | B32: 626 | C32: Autres
A33: M.II.R.C.63 | B33: 63 | C33: IMPÔTS ET TAXES | D33: =D34+D35+D36
A34: M.II.R.C.631 | B34: 631 | C34: Impôts et Taxes locales
A35: M.II.R.C.632 | B35: 632 | C35: Impôts sur ____
A36: M.II.R.C.633 | B36: 633 | C36: Autres impôts et Taxes
A37: M.II.R.C.64 | B37: 64 | C37: CHARGES DE PERSONNEL | D37: =SUM(D38:D39)
A38: M.II.R.C.641 | B38: 641 | C38: Frais de personnel
A39: M.II.R.C.642 | B39: 642 | C39: Charges sociales
A40: M.II.R.C.65 | B40: 65 | C40: AUTRES CHARGES | D40: =SUM(D41:D43)
A41: M.II.R.C.651 | B41: 651 | C41: Remboursement de frais
...

Sheet M.III.HS_BILAN
B1: Nom de l'institution | D1: ='M.0.INFO.G'!C1
B2: Code de l'institution | D2: ='M.0.INFO.G'!C2
B3: Date des rapports | D3: ='M.0.INFO.G'!C3
B4: Rapport | D4: M.III.ENGAGEMENT HORS BILAN
A6: CODE | B6: N° compte | C6: LIBELLES | D6: Montant
A7: M.III.HB.901 | B7: 90 | C7: ENGAGEMENTS DONNES | D7: 4000000
A8: M.III.HB.9011 | B8: 901 | C8: Engagements de financement | D8: 1500000
A9: M.III.HB.9012 | B9: 902 | C9: Engagements de garanties | D9: 2300000
A10: M.III.HB.902 | B10: 909 | C10: Autres engagements donnés | D10: 200000
A11: M.III.HB.9021 | B11: 91 | C11: ENGAGEMENTS RECUS | D11: 2050000
A12: M.III.HB.9022 | B12: 911 | C12: Engagements de financement | D12: 900000
A13: M.III.HB.91 | B13: 912 | C13: Engagements de garanties | D13: 1100000
A14: M.III.HB.911 | B14: 919 | C14: Autres engagements reçus | D14: 50000
A15: M.III.HB.912 | B15: 97 | C15: ENGAGEMENTS DE CREDIT-BAIL | D15: 2000000
A16: M.III.HB.97 | B16: 971 | C16: Engagements de credit-bail mobilier | D16: 750000
A17: M.III.HB.971 | B17: 972 | C17: Engagements de credit-bail immobilier | D17: 1250000
A18: M.III.HB.T | C18: TOTAL GENERAL | D18: 8050000

Sheet M.IV.IMPAYE
B1: Nom de l'institution | C1: ='M.0.INFO.G'!C1
B2: Code de l'institution | C2: ='M.0.INFO.G'!C2
B3: Date des rapports | C3: ='M.0.INFO.G'!C3
B4: Rapport | C4: M.IV.SITUATION DES IMPAYES SUR CREDIT
A6: CODE | B6: ELEMENT | C6: Nombres de prêts | D6: % | E6: Capital restant dû | F6: % | G6: Montant des dépôts nantis ou en garantie | H6: % du capital couvert
A7: M.IV.IMP.1 | B7: A jour | D7: =IF($C$14=0,0,C7/$C$14) | F7: =IF($E$14=0,0,E7/$E$14) | H7: =IF(E7=0,0,G7/E7)
A8: M.IV.IMP.2 | B8: Retards de 1 à 29 jours | D8: =IF($C$14=0,0,C8/$C$14) | F8: =IF($E$14=0,0,E8/$E$14) | H8: =IF(E8=0,0,G8/E8)
A9: M.IV.IMP.3 | B9: Retards de 30 à 89 jours | D9: =IF($C$14=0,0,C9/$C$14) | F9: =IF($E$14=0,0,E9/$E$14) | H9: =IF(E9=0,0,G9/E9)
A10: M.IV.IMP.4 | B10: Retards de 90 à 179 jours | D10: =IF($C$14=0,0,C10/$C$14) | F10: =IF($E$14=0,0,E10/$E$14) | H10: =IF(E10=0,0,G10/E10)
A11: M.IV.IMP.5 | B11: Retards de 180 à 359 jours | D11: =IF($C$14=0,0,C11/$C$14) | F11: =IF($E$14=0,0,E11/$E$14) | H11: =IF(E11=0,0,G11/E11)
A12: M.IV.IMP.6 | B12: Retards de 360 à 719 jours | D12: =IF($C$14=0,0,C12/$C$14) | F12: =IF($E$14=0,0,E12/$E$14) | H12: =IF(E12=0,0,G12/E12)
A13: M.IV.IMP.7 | B13: Retards de plus de 720 jours | D13: =IF($C$14=0,0,C13/$C$14) | F13: =IF($E$14=0,0,E13/$E$14) | H13: =IF(E13=0,0,G13/E13)
A14: M.IV.IMP.8 | B14: Total de l'encours | C14: =C7+C8+C9+C10+C11+C12+C13 | D14: =IF($C$14=0,0,C14/$C$14) | E14: =E7+E8+E9+E10+E11+E12+E13 | F14: =IF($E$14=0,0,E14/$E$14) | G14: =G7+G8+G9+G10+G11+G12+G13 | H14: =IF(E14=0,0,G14/E14)
A20: CODE | B20: ELEMENT | C20: Capital restant dû | D20: % | E20: Norme
A21: M.IV.IMP.9 | B21: Retard de plus de 1 jour (PAR 1) | C21: =SUM(E8:E13) | D21: =IF($E$14=0,0,C21/$E$14) | E21: 0.1
A22: M.IV.IMP.10 | B22: Retard de plus de 30 jours (PAR 30) | C22: =SUM(E9:E13) | D22: =IF($E$14=0,0,C22/$E$14) | E22: 0.05
A23: M.IV.IMP.11 | B23: Rétards de plus de 90 jours (PAR 90) | C23: =SUM(E10:E13) | D23: =IF($E$14=0,0,C23/$E$14) | E23: 0.02

Sheet M.V.PFC
B1: Nom de l'institution | C1: ='M.0.INFO.G'!C1
B2: Code de l'institution | C2: ='M.0.INFO.G'!C2
B3: Date des rapports | C3: ='M.0.INFO.G'!C3
B4: Rapport | C4: M.V.DONNES SUR LE PORTEFEUILLE CREDIT
A6: CODE | B6: ELEMENT | C6: Montant
A7: M.V.PFC.1 | B7: Valeur totale des prêts débloqués depuis le 1er janvier de l'année en cours | C7: =+M.XV.RECAP!D28
A8: M.V.PFC.2 | B8: Nombre de crédits en cours | C8: =M.IV.IMPAYE!C14
A9: M.V.PFC.3 | B9: Solde de crédits sains en cours | C9: =C10+C11+C12
A10: M.V.PFC.4 | B10: Court terme : | C10: =+M.I.BILAN!D35
A11: M.V.PFC.5 | B11: Moyen terme : | C11: =+M.I.BILAN!D38
A12: M.V.PFC.6 | B12: Long terme : | C12: =+M.I.BILAN!D39
A13: M.V.PFC.7 | B13: Solde brut des crédits en souffrance de 30 jours et plus (en fin de période) | C13: =+M.I.BILAN!D41
A14: M.V.PFC.8 | B14: Provisions | C14: =+M.I.BILAN!E41
A15: M.V.PFC.9 | B15: Solde net des crédits en souffrance | C15: =+C13-C14

Sheet M.VI.ADM.DIR
B1: Nom de l'institution | C1: ='M.0.INFO.G'!C1 | I1: s
B2: Code de l'institution | C2: ='M.0.INFO.G'!C2
B3: Date des rapports | C3: ='M.0.INFO.G'!C3
B4: Rapport | C4: M.VI.SITUATION DES CREDITS ACCORDES AUX DIRIGEANTS ET ADMINISTRATEURS (A)
A6: N°. | B6: Nom et prénoms | C6: Fonction | D6: Date d'octroi | E6: Montant initial | F6: Solde | G6: Retard en capital | H6: Provision comptabilisée | I6: Garantie
A7: 1
A8: 2
A9: 3
A10: 4
A11: 5
A12: 6
A13: 7
A14: 8
A15: 9
A16: 10
A17: 11
A18: 12
... A151: 145
A152: Total | B152: N/A | C152: N/A | D152: - | E152: =SUM(E7:E151) | F152: =SUM(F7:F151) | G152: =SUM(G7:G151) | H152: =SUM(H7:H151) | I152: =SUM(I7:I151)

Sheet M.VII.PERSONNEL
B1: Nom de l'institution | C1: ='M.0.INFO.G'!C1
B2: Code de l'institution | C2: ='M.0.INFO.G'!C2
B3: Date des rapports | C3: ='M.0.INFO.G'!C3
B4: Rapport | C4: M.VII.SITUATION DES CREDITS ACCORDES AU PERSONNEL
A6: N°. | B6: Nom et Prénoms | C6: Date originale | D6: Montant original | E6: Solde | F6: Retard en capital | G6: Provision comptabilisée | H6: Garantie
A7: 1
A8: 2
A9: 3
A10: 4
A11: 5 | H11: 0
A12: 6 | H12: 0
A13: 7 | H13: 0
A14: 8
A15: 9
A16: 10
A17: 11
A18: 12
A19: 13
A20: 14
A21: 15
A22: 16
A23: 17
A24: 18
A25: 19
... A196: 190
A197: Total | B197: N/A | C197: N/A | D197: =SUM(D7:D196) | E197: =SUM(E7:E196) | F197: =SUM(F7:F196) | G197: =SUM(G7:G196) | H197: =SUM(H7:H196)

Sheet M.VIII.DIX.DEB
B1: Nom de l'institution | C1: ='M.0.INFO.G'!C1
B2: Code de l'institution | C2: ='M.0.INFO.G'!C2
B3: Date des rapports | C3: ='M.0.INFO.G'!C3
B4: Rapport | C4: M.VIII.DIX (10) DEBITEURS LES PLUS IMPORTANTS
A6: N°. | B6: Nom et prénoms | C6: Date originale | D6: Montant original | E6: Solde | F6: Retard en capital | G6: Provision comptabilisée | H6: Garantie | I6: Ratio de limitation des engagements pris sur une seule signature
A7: 1 | I7: =IF(M.X.RSL!G39=0,0,(E7/M.X.RSL!G39)*100)
A8: 2 | I8: =IF(M.X.RSL!G39=0,0,(E8/M.X.RSL!G39)*100)
A9: 3 | F9: 0 | G9: 0 | I9: =IF(M.X.RSL!G39=0,0,(E9/M.X.RSL!G39)*100)
A10: 4 | F10: 0 | G10: 0 | H10: 0 | I10: =IF(M.X.RSL!G39=0,0,(E10/M.X.RSL!G39)*100)
A11: 5 | F11: 0 | G11: 0 | H11: 0 | I11: =IF(M.X.RSL!G39=0,0,(E11/M.X.RSL!G39)*100)
A12: 6 | F12: 0 | G12: 0 | I12: =IF(M.X.RSL!G39=0,0,(E12/M.X.RSL!G39)*100)
A13: 7 | F13: 0 | G13: 0 | I13: =IF(M.X.RSL!G39=0,0,(E13/M.X.RSL!G39)*100)
A14: 8 | F14: 0 | G14: 0 | I14: =IF(M.X.RSL!G39=0,0,(E14/M.X.RSL!G39)*100)
A15: 9 | F15: 0 | G15: 0 | I15: =IF(M.X.RSL!G39=0,0,(E15/M.X.RSL!G39)*100)
A16: 10 | F16: 0 | G16: 0 | I16: =IF(M.X.RSL!G39=0,0,(E16/M.X.RSL!G39)*100)
A17: TOTAL | B17: N/A | C17: N/A | D17: =SUM(D7:D16) | E17: =SUM(E7:E16) | F17: =SUM(F7:F16) | G17: =SUM(G7:G16) | H17: =SUM(H7:H16)

Sheet M.IX.SG
B1: Nom de l'institution | C1: ='M.0.INFO.G'!C1
B2: Code de l'institution | C2: ='M.0.INFO.G'!C2
B3: Date des rapports | C3: ='M.0.INFO.G'!C3
B4: Rapport | C4: M.IX.DONNEES SUR LES ACTIVITES ET STATISTIQUES GENERALES
A6: CODE | B6: ELEMENT | C6: INDICATEURS | F6: INSCRIRE LE DETAIL DANS CETTE COLONNE
F7: Total | G7: Agences ou Caisses de base | H7: Points de service
A8: M.IX.SG.1 | B8: A | D8: Nombre d'institutions en opération, si affialiation à un réseau ou nombre de succursales, de bureaux ou d'agences en opération si non affialiation à un réseau. | F8: 102 | G8: 103 | H8: 104
D9: Nombre total de membres/clients des institutions en opération si affialiation à un réseau ou de membres de succursales, de bureaux ou d'agences d'une institution en opération au cas de non affiliation à un réseau. | F9: Individuel | G9: Groupement
G10: Groupes | H10: Personnes
A12: M.IX.SG.2 | B12: B | C12: TOTAL | D12: 201 | F12: 202 | G12: 203 | H12: 204
D13: Nombre de femmes membres/clientes. | F13: Individuel | G13: Groupement
G14: Groupes | H14: Personnes
A16: M.IX.SG.3 | B16: C | C16: TOTAL | D16: 301 | F16: 302 | G16: 303 | H16: 304
D17: Nombre de crédits en cours accordés aux femmes. | F17: Individuel | G17: Groupement
G18: Groupes | H18: Personnes
A19: M.IX.SG.4 | B19: D | C19: TOTAL | D19: 401 | F19: 402 | G19: 403 | H19: 404
D20: Volume de crédits en cours accordés aux femmes. | F20: Individuel | G20: Groupement
A21: M.IX.SG.5 | B21: E | C21: TOTAL | D21: 501 | F21: 502 | G21: 503
A22: M.IX.SG.6 | B22: F | C22: Nombre total de Dirigeants du réseau ou de l'institution. | F22: 602
A23: M.IX.SG.7 | B23: G | C23: Pourcentage des dirigeants de sexe féminin en poste aux différents organes decisionnels et conseils. | F23: 702
D24: Nombre d'employés total au sein des institutions affiliées à un réseau ou au sein de succursales, bureaux et agences d'une institution. | F24: Femmes | G24: Hommes
A26: M.IX.SG.8 | B26: H | C26: TOTAL | D26: 801 | F26: 802 | G26: 803
A27: M.IX.SG.9 | B27: I | C27: Nombre total d'employés au sein du réseau des 2e et 3e niveaux du réseau. | F27: 902
A28: M.IX.SG.10 | B28: J | C28: Nombre d'agents de crédit | F28: 1002

Sheet M.X.RSL
B1: Nom de l'institution | C1: ='M.0.INFO.G'!C1
B2: Code de l'institution | C2: ='M.0.INFO.G'!C2
B3: Date des rapports | C3: ='M.0.INFO.G'!C3
B4: Rapport | C4: M.X.ANNEXE RELATIVE AU CALCUL DES RATIOS DE SOLVABILITE ET DE LIQUIDITE
A6: CODE | B6: ELEMENT | C6: N° Compte | D6: FONDS PROPRES DE BASE | E6: MONTANT GNF | F6: TAUX DE PONDERATION | G6: MONTANT RETENU
A7: M.X.RSL.1 | B7: A | C7: 50 | D7: Provisions du passif / fonds pour risques bancaires généraux | E7: =+M.I.BILAN!F132 | F7: 100 | G7: =+E7*F7/100
A8: M.X.RSL.2 | C8: 572 | D8: Capital libéré fixe ou dont le remboursement peut être bloqué | E8: =+M.I.BILAN!F146 | F8: 100 | G8: =+E8*F8/100
A9: M.X.RSL.3 | C9: 52 | D9: Report à nouveau | E9: =M.I.BILAN!F134 | F9: 100 | G9: =+E9*F9/100
A10: M.X.RSL.4 | C10: 54 | D10: Réserves facultatives | E10: =+M.I.BILAN!F141 | F10: 100 | G10: =+E10*F10/100
A11: M.X.RSL.5 | C11: 55 | D11: Réserves légales | E11: =+M.I.BILAN!F142 | F11: 100 | G11: =+E11*F11/100
A12: M.X.RSL.6 | C12: 56 | D12: Fonds de dotation impartageable, à caractère de réserve | E12: =+M.I.BILAN!F143 | F12: 100 | G12: =+E12*F12/100
A13: M.X.RSL.7 | C13: 58 | D13: Fonds de sécurité des réseaux | E13: =+M.I.BILAN!F147 | F13: 100 | G13: =+E13*F13/100
A14: M.X.RSL.8 | C14: 59 | D14: Excédent | E14: =IF(M.I.BILAN!D148>0,M.I.BILAN!D148,0) | F14: 15 | G14: =+E14*F14/100
A15: M.X.RSL.9 | D15: TOTAL FONDS PROPRES DE BASE (FPB) | E15: =E7+E8+E9+E10+E11+E12+E13+E14 | G15: =SUM(G7:G14)
A16: M.X.RSL.10 | B16: A1 | D16: A DEDUIRE
A17: M.X.RSL.12 | C17: 42 | D17: Immobilisations incorporelles | E17: =M.I.BILAN!F66 | F17: 100 | G17: =F17*E17/100
A18: M.X.RSL.13 | D18: Actions propres détenues, évaluées à leur valeur comptable | F18: 100 | G18: =+E18*F18/100
A19: M.X.RSL.14 | C19: 401 | D19: Toute participation dans une autre institution financière régulée (établissement de crédit, IFI, compagnie d’assurance, fonds de garantie des dépôts et de résolution, ou autre | E19: =+M.I.BILAN!F61 | F19: 100 | G19: =+E19*F19/100
A20: M.X.RSL.15 | C20: 571 | D20: Capital social souscrit non libéré | E20: =M.I.BILAN!F145 | F20: 100 | G20: =F20*E20*1/100
A21: M.X.RSL.16 | C21: 59 | D21: Déficit d’exercice en instance d’approbation | E21: =IF(M.I.BILAN!D148<0,M.I.BILAN!D148,0) | F21: 100 | G21: =+E21*F21/100
A22: M.X.RSL.17 | C22: 353 | D22: Dividendes à payer | E22: =+M.I.BILAN!F125 | F22: 100 | G22: =+E22*F22/100
A23: M.X.RSL.18 | D23: Provisions complémentaires à constituer pour dépréciation ou risque de non recouvrement d’actifs, ou pour charges et pertes diverses | F23: 100 | G23: =+E23*F23/100
A24: M.X.RSL.19 | D24: TOTAL A DEDUIRE | E24: =E17+E18+E19+E21+E22+E23 | G24: =SUM(G17:G23)
A25: M.X.RSL.20 | B25: A2 | D25: MONTANT FONDS PROPRES DE BASE (A-A1) | E25: =E15-E24 | G25: =G15-G24
A27: CODE | B27: ELEMENT | C27: N° Compte | D27: FONDS PROPRES COMPLEMENTAIRES (FPC) | E27: MONTANT GNF | F27: TAUX DE PONDERATION | G27: MONTANT RETENU
A28: M.X.RSL.21 | B28: B | D28: Réserves de réévaluation certifiées par le commissaire aux comptes | F28: 100 | G28: =+E28*F28/100
A29: M.X.RSL.22 | C29: 342 | D29: Comptes bloqués d’associés | E29: =+M.I.BILAN!F120 | F29: 100 | G29: =+E29*F29/100
A30: M.X.RSL.23 | C30: 51 | D30: Subventions d’investissement amortissables au rythme des immobilisations financières | E30: =+M.I.BILAN!F133 | F30: 100 | G30: =+E30*F30/100
A31: M.X.RSL.24 | C31: 53 | D31: Dettes bancaires subordonnées à durée inderminée ou terme ≥ 5 ans | E31: =+M.I.BILAN!F136 | F31: 100 | G31: =+E31*F31/100
A32: M.X.RSL.25 | D32: TOTAL FONDS PROPRES COMPLEMENTAIRES | E32: =E28+E29+E30+E31 | F32: 100 | G32: =+E32*F32/100
A33: M.X.RSL.26 | B33: B1 | D33: A DEDUIRE | F33: 100 | G33: =+E33*F33/100
A34: M.X.RSL.27 | C34: 403 | D34: Les titres et dettes subordonnés détenus dans d’autres institutions financières | E34: =+M.I.BILAN!F63 | F34: 100 | G34: =+E34*F34/100
D35: Les comptes courants d’associés bloqués dans d’autres institutions financières | F35: 100 | G35: =+E35*F35/100
A36: M.X.RSL.28 | D36: TOTAL A DEDUIRE | E36: =E34+E35 | F36: 100 | G36: =+E36*F36/100
A37: M.X.RSL.29 | B37: B2 | D37: MONTANT FONDS PROPRES COMPLEMENTAIRES (B-B1) | E37: =E32-E36 | F37: 100 | G37: =+E37*F37/100
C38: NB: MONTANT DE FPC ADMIS (<=50% FPB)
A39: M.X.RSL.30 | B39: C | D39: FONDS PROPRES NETS (FPB+FPC) | E39: =E25+E37 | G39: =IF((G37<=0.5*G25),G37+G25,(G25+0.5*G25))
C41: DETERMINATION DE L'ACTIF NET A RISQUE
A42: CODE | B42: ELEMENT | C42: N° Compte | D42: LIBELLES | E42: MONTANT GNF | F42: TAUX DE PONDERATION | G42: MONTANT RETENU
A43: M.X.RSL.31 | D43: Comptes de trésorerie | E43: 0
...

Sheet M.XI.RPCS
B1: Nom de l'institution | C1: ='M.0.INFO.G'!C1
B2: Code de l'institution | C2: ='M.0.INFO.G'!C2
B3: Date des rapports | C3: ='M.0.INFO.G'!C3
B4: Rapport | C4: M.XI.REPARTITION DU PORTEFEUILLE DE CREDIT PAR SECTEUR
A6: CODE | B6: ELEMENT | C6: Agriculture Elevage Pêche | D6: Travaux publics Bâtiments Logements | E6: Commerce Restaurant Hôtellerie | F6: Industrie Artisanat | G6: Transport Communication | H6: Autres | I6: TOTAL
A7: M.XI.RPCS.1 | B7: Non résidents | I7: =C7+D7+E7+F7+G7+H7
A8: M.XI.RPCS.2 | B8: Ménages | I8: =C8+D8+E8+F8+G8+H8
A9: M.XI.RPCS.3 | B9: ISBLSM (Institutions sans but lucratif au service des menages) | I9: =C9+D9+E9+F9+G9+H9
A10: M.XI.RPCS.4 | B10: Autres | I10: =C10+D10+E10+F10+G10+H10
A12: M.XI.RPCS.5 | B12: TOTAL | C12: =SUM(C7:C10) | D12: =SUM(D7:D10) | E12: =SUM(E7:E10) | F12: =SUM(F7:F10) | G12: =SUM(G7:G10) | H12: =SUM(H7:H10) | I12: =SUM(I7:I10)
A14: M.XI.RPCS.6 | B14: % dans les crédits de l'IMF | C14: =IF($I$12=0,0,+C12/$I$12*100) | D14: =IF($I$12=0,0,+D12/$I$12*100) | E14: =IF($I$12=0,0,+E12/$I$12*100) | F14: =IF($I$12=0,0,+F12/$I$12*100) | G14: =IF($I$12=0,0,+G12/$I$12*100) | H14: =IF($I$12=0,0,+H12/$I$12*100) | I14: =IF($I$12=0,0,+I12/$I$12*100)
A16: M.XI.RPCS.7 | B16: Hommes | I16: =+C16+D16+E16+F16+G16+H16
A17: M.XI.RPCS.8 | B17: Femmes | I17: =+C17+D17+E17+F17+G17+H17
A18: M.XI.RPCS.9 | B18: Personnes morales | I18: =+C18+D18+E18+F18+G18+H18
A21: M.XI.RPCS.10 | B21: Moyenne Guinée | I21: =+C21+D21+E21+F21+G21+H21
A22: M.XI.RPCS.11 | B22: Basse Guinée | I22: =+C22+D22+E22+F22+G22+H22
A23: M.XI.RPCS.12 | B23: Guinée Forestière | I23: =+C23+D23+E23+F23+G23+H23
A24: M.XI.RPCS.13 | B24: Haute Guinée | I24: =+C24+D24+E24+F24+G24+H24
A27: M.XI.RPCS.14 | B27: Moyenne Guinée | C27: =IF($C$12=0,0,+C21/$C$12*100) | D27: =IF($D$12=0,0,+D21/$D$12*100) | E27: =IF($E$12=0,0,+E21/$E$12*100) | F27: =IF($F$12=0,0,+F21/$F$12*100) | G27: =IF($G$12=0,0,+G21/$G$12*100) | H27: =IF($H$12=0,0,+H21/$H$12*100) | I27: =IF($I$12=0,0,+I21/$I$12*100)
A28: M.XI.RPCS.15 | B28: Basse Guinée | C28: =IF($C$12=0,0,+C22/$C$12*100) | D28: =IF($D$12=0,0,+D22/$D$12*100) | E28: =IF($E$12=0,0,+E22/$E$12*100) | F28: =IF($F$12=0,0,+F22/$F$12*100) | G28: =IF($G$12=0,0,+G22/$G$12*100) | H28: =IF($H$12=0,0,+H22/$H$12*100) | I28: =IF($I$12=0,0,+I22/$I$12*100)
A29: M.XI.RPCS.16 | B29: Guinée Forestière | C29: =IF($C$12=0,0,+C23/$C$12*100) | D29: =IF($D$12=0,0,+D23/$D$12*100) | E29: =IF($E$12=0,0,+E23/$E$12*100) | F29: =IF($F$12=0,0,+F23/$F$12*100) | G29: =IF($G$12=0,0,+G23/$G$12*100) | H29: =IF($H$12=0,0,+H23/$H$12*100) | I29: =IF($I$12=0,0,+I23/$I$12*100)
A30: M.XI.RPCS.17 | B30: Haute Guinée | C30: =IF($C$12=0,0,+C24/$C$12*100) | D30: =IF($D$12=0,0,+D24/$D$12*100) | E30: =IF($E$12=0,0,+E24/$E$12*100) | F30: =IF($F$12=0,0,+F24/$F$12*100) | G30: =IF($G$12=0,0,+G24/$G$12*100) | H30: =IF($H$12=0,0,+H24/$H$12*100) | I30: =IF($I$12=0,0,+I24/$I$12*100)

Sheet M.XII.RCS
B1: Nom de l'institution | C1: ='M.0.INFO.G'!C1
B2: Code de l'institution | C2: ='M.0.INFO.G'!C2
B3: Date des rapports | C3: ='M.0.INFO.G'!C3
B4: Rapport | C4: M.XII.ETAT DE RECOUVREMENTS DES CREANCES EN SOUFFRANCE RADIEES DU PORTEFEUILLE CREDIT
A6: CODE | B6: Tranches de jours de retard | C6: Solde des crédits au 31 décembre précédent | D6: RECOUVREMENT AU COURS DE L'EXERCICE
D7: 1er trimestre | E7: 2ème trimestre | F7: 3ème trimestre | G7: 4ème trimestre | H7: TOTAL
C8: Principal | D8: Principal | E8: Principal | F8: Principal | G8: Principal | H8: Principal
A9: M.XII.RCS.1 | B9: (91 à 180 jours)
A10: M.XII.RCS.2 | B10: (181 à 365 jours)
A11: M.XII.RCS.3 | B11: (366 jours à 720 jours)
A12: M.XII.RCS.4 | B12: (plus de 720 jours)
A13: M.XII.RCS.5 | B13: TOTAL | C13: =SUM(C9:C12) | D13: =SUM(D9:D12) | E13: =SUM(E9:E12) | F13: =SUM(F9:F12) | G13: =SUM(G9:G12) | H13: =SUM(H9:H12)

Sheet M.XIII.OATA
A1: Nom de l'institution | C1: ='M.0.INFO.G'!C1
A2: Code de l'institution | C2: ='M.0.INFO.G'!C2
A3: Date des rapports | C3: ='M.0.INFO.G'!C3
A4: Rapport | C4: M.XIII.RATIO DE DIVERSIFICATION ET DE LIMITATION DES PARTICIPATIONS AUTRES QUE DANS LES IFI
B5: A) - RATIO DE DIVERSIFICATION
A7: CODE | B7: ELEMENT | C7: N° Compte | D7: LIBELLE | E7: MONTANT GNF
A8: M.XIII.OATA.A.1 | B8: I | C8: 715 | D8: Produits non bancaires | E8: =M.II.RESULTAT!D88+M.II.RESULTAT!D98
A9: M.XIII.OATA.A.2 | B9: II | D9: TOTAL DES PRODUITS | E9: =M.II.RESULTAT!D61
A10: M.XIII.OATA.A.3 | B10: I/II | D10: RATIO DE DIVERSIFICATION (I/II) : La norme à respecter est de 5% maximum | E10: =IF(E9=0,0,E8/E9*100)
B12: B) - RATIO DE LIMITATION DES PARTICIPATIONS AUTRES DANS LES IFI
A14: CODE | B14: ELEMENT | C14: N° Compte | D14: LIBELLE | E14: MONTANT GNF
B15: I | D15: Somme des Titres de Participation | E15: =+E16
A16: M.XIII.OATA.B.2 | B16: II | C16: 402 | D16: Autres Titres de participation | E16: =M.I.BILAN!F62
A17: M.XIII.OATA.B.3
A18: M.XIII.OATA.B.4 | D18: Fonds Propres Nets | E18: =M.X.RSL!G39
A19: M.XIII.OATA.B.5 | B19: I/II | D19: RATIO DE LIMITATION DES PARTICIPATIONS AUTRES QUE DANS LES IFI (I/II) : La norme à respecter est de 25% maximum | E19: =IF(E18=0,0,E15/E18*100)
B21: C) - COUVERTURE DES IMMOBILISATIONS PAR LES FONDS PROPRES
A23: CODE | B23: ELEMENT | C23: N° Compte | D23: LIBELLE | E23: MONTANT GNF
A24: M.XIII.OATA.C.1 | B24: I | C24: 402 | D24: Autres Titres de Participations | E24: =M.I.BILAN!F62
A25: M.XIII.OATA.C.2 | C25: 404 | D25: Autres Titres immobilisées hors Institutions Financières | E25: =M.I.BILAN!F64
A26: M.XIII.OATA.C.3 | C26: 41 | D26: Dépôts et cautionnements (long terme) | E26: =M.I.BILAN!F65
A27: M.XIII.OATA.C.4 | C27: 43 | D27: Immobilisations corporelles | E27: =M.I.BILAN!F69
A28: M.XIII.OATA.C.5 | C28: 44 | D28: Immobilisations en cours | E28: =M.I.BILAN!F75
A29: M.XIII.OATA.C.6 | B29: II | D29: Total des Immobilisations | E29: =SUM(E24:E28)
A30: M.XIII.OATA.C.7 | D30: Fonds Propres Nets | E30: =M.X.RSL!G39
A31: M.XIII.OATA.C.8 | B31: I/II | D31: RATIO DE COUVERTURE DES IMMOBILISATIONS PAR LES FONDS PROPRES (I/II) : La norme à respecter est de 50% maximum | E31: =IF(E30=0,0,E29/E30*100)
D34: D) - CONSTITUTIONS DES RESERVES DES IMFS
A36: CODE | B36: ELEMENT | C36: N°Compte | D36: LIBELLE | E36: MONTANT GNF
A37: M.XIII.OATA.D.1 | B37: I | D37: EXCEDENT | E37: =M.I.BILAN!D148
A38: M.XIII.OATA.D.2 | B38: II | D38: RESERVE LEGALE OBLIGATOIRE (N-1)
A39: M.XIII.OATA.D.3 | D39: RESERVE LEGALE OBLIGATOIRE (N) | E39: =M.I.BILAN!F142
A42: CODE | B42: ELEMENT | C42: N°Compte | D42: LIBELLE | E42: MONTANT GNF
A43: M.XIII.OATA.E.1 | B43: III | D43: Variation en montant de la Reserve légale Obligatoire : (N - N-1) | E43: =E39-E38
A44: M.XIII.OATA.E.2 | B44: III/I | D44: RATIO DE RESERVE LEGALE OBLIGATOIRE (III/I) : La norme à respecter est de 15% des bénéfices de l'exercice minimum. | E44: =IF(E37=0,0,E43/E37*100)

Sheet M.XIV.FS
B1: Nom de l'institution | C1: ='M.0.INFO.G'!C1
B2: Code de l'institution | C2: ='M.0.INFO.G'!C2
B3: Date des rapports | C3: ='M.0.INFO.G'!C3
B4: Rapport | C4: M.XIV.FONDS DE SOLIDARITE FINANCIERE
A6: CODE | B6: ELEMENT | C6: LIBELLE | D6: MONTANT GNF
A7: M.XIV.FS.A.1 | B7: I | C7: Total Actif brut moyen et des engagements par signature (N-1)
A8: M.XIV.FS.A.2 | B8: II | C8: Total Actif brut moyen | D8: =IFERROR(M.XXII.INDIC.PRUDENTIELS!C38,0)
A9: M.XIV.FS.A.3 | B9: III | C9: Variation de l'actif moyen (II-I) | D9: =IFERROR(+D8-D7,0)
A10: M.XIV.FS.A.4 | B10: IV | C10: Engagements par signature (N) | D10: =+M.III.HS_BILAN!D7
A11: M.XIV.FS.A.5 | B11: V | C11: Base de calcul du Fonds de solidarité (III+IV) | D11: =IFERROR(+D9+D10,0)
C13: RESPECT DE L'INSTRUCTION
A14: CODE | B14: ELEMENT | C14: LIBELLE | D14: MONTANT GNF
A15: M.XIV.FS.B.1 | B15: VIII | C15: Fonds de solidarité Financière (N) | D15: =M.I.BILAN!F147
A16: M.XIV.FS.B.2 | B16: IX | C16: Fonds de solidarité Financière (N-1)
A17: M.XIV.FS.B.3 | B17: X | C17: Variation du Fonds de solidarité financière | D17: =D15-D16
A18: M.XIV.FS.B.4 | B18: X/V | C18: Procéder de contrôle: le rapport du calcul (X/V) doit être >= 2% | D18: =IF(D17=0,0,D17/D11*100)

Sheet M.XVI.CERS
B1: Nom de l'institution | C1: ='M.0.INFO.G'!C1
B2: Code de l'institution | C2: ='M.0.INFO.G'!C2
B3: Date des rapports | C3: ='M.0.INFO.G'!C3
B4: Rapport | C4: M.XVI.COUVERTURE DES EMPLOIS A MOYEN ET LONG TERME PAR LES RESSOURCES STABLES
A6: CODE | B6: ELEMENT | C6: N° Compte | D6: LIBELLE | E6: MONTANT GNF
A7: M.XIX.CERS.1 | B7: I | D7: EMPLOIS
A8: M.XIX.CERS.2 | C8: 12 | D8: Secteur financier, PMLT, éhéances supérieures à 2 ans | E8: =M.I.BILAN!F28
A9: M.XIX.CERS.4 | C9: 202 | D9: Crédit à moyen terme, | E9: =M.I.BILAN!F38
A10: M.XIX.CERS.5 | C10: 203 | D10: Crédit à long terme, | E10: =M.I.BILAN!F39
A11: M.XIX.CERS.6 | C11: 21 | D11: Crédits en souffrance | E11: =+M.I.BILAN!F41
A12: M.XIX.CERS.7 | C12: 323 | D12: Autres créances en souffrance | E12: =+M.I.BILAN!F52
A13: M.XIX.CERS.8 | C13: 4 | D13: Immobilisations | E13: =+M.I.BILAN!F59
A14: M.XIX.CERS.9 | D14: TOTAL EMPLOIS | E14: =SUM(E8:E13)
A15: M.XIX.CERS.10 | B15: II | D15: RESSOURCES
A16: M.XIX.CERS.11 | C16: 17 | D16: Emprunts à moyen et long terme auprès du secteur financier (Moins compte 178: dettes rattachées) | E16: =+M.I.BILAN!F88-M.I.BILAN!F95
A17: M.XIX.CERS.12 | C17: 18 | D17: Ressources affectées (échéance supérieure à 2ans)
A18: M.XIX.CERS.13 | C18: 242 | D18: Quôte part des dépôts à terme (DAT), échéances sup à 2 ans | E18: =M.I.BILAN!F105
A19: M.XIX.CERS.14 | C19: 243 | D19: Quôte part des dépôts de garantie, couvrant des crédits à moyen et long terme | E19: =M.I.BILAN!F108
A20: M.XIX.CERS.15 | C20: 50 | D20: Provisions du passif | E20: =M.I.BILAN!F132
A21: M.XIX.CERS.16 | C21: 51 | D21: Subvention d'investissement | E21: =M.I.BILAN!F133
A22: M.XIX.CERS.17 | C22: 52 | D22: Report à nouveau | E22: =M.I.BILAN!F134
A23: M.XIX.CERS.18 | C23: 53 | D23: Dettes subordonnées & assimilées éligibles aux fonds propres | E23: =M.I.BILAN!F135
A24: M.XIX.CERS.19 | C24: 54 | D24: Réserves facultatives | E24: =M.I.BILAN!F141
A25: M.XIX.CERS.20 | C25: 55 | D25: Réserves générales | E25: =M.I.BILAN!F142
A26: M.XIX.CERS.21 | C26: 56 | D26: Fonds de dotation impartageable, à caractère de réserve | E26: =M.I.BILAN!F143
A27: M.XIX.CERS.22 | C27: 572 | D27: Capital social fixe ou dont le remboursement peut être bloqué, libéré | E27: =M.I.BILAN!F146
A28: M.XIX.CERS.23 | C28: 58 | D28: Fonds de solidarité financière des réseaux | E28: =M.I.BILAN!F147
A29: M.XIX.CERS.24 | C29: 59 | D29: 15% du compte 59 excédent ou 100% du déficit ( en cours d'affectation) | E29: =M.I.BILAN!F148
A30: M.XIX.CERS.25 | D30: TOTAL RESSOURCES | E30: =SUM(E16:E29)
A32: M.XIX.CERS.26 | B32: RATIO DE COUVERTURE DES EMPLOIS (ML&T) PAR LES RESSOURCES STABLES (II/I) : La norme à respecter est de 100% minimum | E32: =IF(E14=0,0,E30/E14*100)

Sheet M.XV.RECAP
B1: Nom de l'institution | C1: ='M.0.INFO.G'!C1
B2: Code de l'institution | C2: ='M.0.INFO.G'!C2
B3: Date des rapports | C3: ='M.0.INFO.G'!C3
B4: Rapport | C4: M.XV.RECAP
A6: CODE | B6: ELEMENT | D6: VALEUR
B7: INFORMATIONS GENERALES
A8: M.XVIII.RECAP.1 | B8: Nombre total de point de couverture des services | D8: =M.IX.SG!F8
A9: M.XVIII.RECAP.2 | B9: Nombre d'agences ou de caisses de base | D9: =M.IX.SG!G8
A10: M.XVIII.RECAP.3 | B10: Nombre de points de service | D10: =M.IX.SG!H8
A11: M.XVIII.RECAP.4 | B11: Nombre d'employés | D11: =+D12+D13
A12: M.XVIII.RECAP.5 | B12: CDI
A13: M.XVIII.RECAP.6 | B13: CDD
A14: M.XVIII.RECAP.7 | B14: Nombre d'agents de crédit | D14: 0
A15: M.XVIII.RECAP.8 | B15: Nombre de clients, membres ou bénéficiaires | D15: =+D16+D17+D18
A16: M.XVIII.RECAP.9 | B16: Hommes
A17: M.XVIII.RECAP.10 | B17: Femmes
A18: M.XVIII.RECAP.11 | B18: Personnes morales
A19: M.XVIII.RECAP.12 | B19: Nombre de crédits accordés depuis le 1er janvier | D19: =+D20+D21+D22
A20: M.XVIII.RECAP.13 | B20: Nombre de crédits accordés aux Hommes
A21: M.XVIII.RECAP.14 | B21: Nombre de crédits accordés aux Femmes
A22: M.XVIII.RECAP.15 | B22: Nombre de crédits accordés aux Personnes morales
A23: M.XVIII.RECAP.16 | B23: Volume des crédits accordés par genre depuis le 1er janvier | D23: =+D24+D25+D26
A24: M.XVIII.RECAP.17 | B24: Femmes
A25: M.XVIII.RECAP.18 | B25: Hommes
A26: M.XVIII.RECAP.19 | B26: Entreprise individuelle ou personnes morales
B27: PORTEFEUILLE DE PRÊTS
A28: M.XVIII.RECAP.20 | B28: Répartition du Volume de financement des crédits par secteur d'activités | D28: =SUM(D29:D34)
A29: M.XVIII.RECAP.21 | B29: Agriculture,Elévage,Pêche
A30: M.XVIII.RECAP.22 | B30: Travaux publics et Batiments
A31: M.XVIII.RECAP.23 | B31: Commerce, Restaurant,Hotélrie
A32: M.XVIII.RECAP.24 | B32: Industrie, Artisanat
A33: M.XVIII.RECAP.25 | B33: Transport, Communication
A34: M.XVIII.RECAP.26 | B34: Autres
A35: M.XVIII.RECAP.27 | B35: Rapport sur la qualité du portefeuille | D35: =SUM(D36,D37)
A36: M.XVIII.RECAP.28 | B36: Portefeuille des crédits à jour | D36: =M.I.BILAN!F34
A37: M.XVIII.RECAP.29 | B37: Portefeuille des crédits en souffrance | D37: =SUM(D38:D43)
A38: M.XVIII.RECAP.30 | B38: 1 - 29 jours
A39: M.XVIII.RECAP.31 | B39: 30 - 89 jours
A40: M.XVIII.RECAP.32 | B40: 90 - 179 jours
A41: M.XVIII.RECAP.33 | B41: 180 - 359 jours
...

Sheet M.XVII.PROV
B1: Nom de l'institution | C1: ='M.0.INFO.G'!C1
B2: Code de l'institution | C2: ='M.0.INFO.G'!C2
B3: Date des rapports | C3: ='M.0.INFO.G'!C3
B4: Rapport | C4: M.XVII.TAUX DE PROVISIONS
A6: CODE | B6: ELEMENT | C6: N° Compte | D6: LIBELLE | E6: Montant en souffrance | F6: Norme | G6: Provisions
A7: M.XX.PROV.2 | D7: Retards de 1 à 29 jours | E7: =M.IV.IMPAYE!E8 | F7: 0 | G7: =E7*F7
A8: M.XX.PROV.3 | D8: Retards de 30 à 89 jours | E8: =M.IV.IMPAYE!E9 | F8: 0.25 | G8: =E8*F8
A9: M.XX.PROV.4 | D9: Retards de 90 à 179 jours | E9: =M.IV.IMPAYE!E10 | F9: 0.5 | G9: =E9*F9
A10: M.XX.PROV.5 | D10: Retards de 180 à 719 jours | E10: =M.IV.IMPAYE!E11+M.IV.IMPAYE!E12 | F10: 0.75 | G10: =E10*F10
A11: M.XX.PROV.6 | D11: Retards de plus de 720 jours | E11: =M.IV.IMPAYE!E13 | F11: 1 | G11: =E11*F11
A12: M.XX.PROV.7 | B12: I | D12: TOTAL PROVISION A CONSTITUER | E12: =E7+E8+E9+E10+E11 | G12: =SUM(G7:G11)
A13: M.XX.PROV.10 | B13: II | D13: TOTAL PROVISIONS CONSTITUEES | G13: =M.I.BILAN!E33
A15: M.XX.PROV.11 | B15: III | D15: RATIO DE TAUX DE PROVISIONS (II/I) : La norme à respecter est de 100% minimum | G15: =IF(G12=0,0,G13/G12*100)

Sheet M.XVIII.DIX.CREANCIERS
B1: Nom de l'institution | C1: ='M.0.INFO.G'!C1
B2: Code de l'institution | C2: ='M.0.INFO.G'!C2
B3: Date des rapports | C3: ='M.0.INFO.G'!C3
B4: Rapport | C4: M.XVIII.DIX (10) CREANCIERS LES PLUS IMPORTANTS, hors secteur régulé
A6: N°. | B6: Nom et prénoms | C6: Nature de Ressource | D6: Date originale | E6: Montant original | F6: Solde | G6: Date d'échéance
A7: 1
A8: 2
A9: 3 | F9: 0 | G9: 0
A10: 4 | F10: 0 | G10: 0
A11: 5 | F11: 0 | G11: 0
A12: 6 | F12: 0 | G12: 0
A13: 7 | F13: 0 | G13: 0
A14: 8 | F14: 0 | G14: 0
A15: 9 | F15: 0 | G15: 0
A16: 10 | F16: 0 | G16: 0
A17: TOTAL | B17: N/A | C17: N/A | D17: N/A | E17: =SUM(E7:E16) | F17: =SUM(F7:F16) | G17: N/A

Sheet M.XIX.CREDITS.RESTRUCTURES
B1: Nom de l'institution | C1: ='M.0.INFO.G'!C1
B2: Code de l'institution | C2: ='M.0.INFO.G'!C2
B3: Date des rapports | C3: ='M.0.INFO.G'!C3
B4: Rapport | C4: M.XIX.LISTE DES CREDITS RESTRUCTURES
A6: N°. | B6: Nom et prénoms | C6: Montant original | D6: Date | E6: Montant restructuré | F6: Date | G6: Solde | H6: Retard en capital | I6: Nombre de jours de retard | J6: Provision comptablisée | K6: Pourcentage couvert | L6: Garantie
A7: 1
A8: 2
A9: =A8+1 | K9: =IF(G9=0,0,J9/G9*100)
A10: =A9+1 | K10: =IF(G10=0,0,J10/G10*100)
A11: =A10+1 | K11: =IF(G11=0,0,J11/G11*100)
A12: =A11+1 | K12: =IF(G12=0,0,J12/G12*100)
A13: =A12+1 | K13: =IF(G13=0,0,J13/G13*100)
A14: =A13+1 | K14: =IF(G14=0,0,J14/G14*100)
A15: =A14+1 | K15: =IF(G15=0,0,J15/G15*100)
A16: =A15+1 | K16: =IF(G16=0,0,J16/G16*100)
A17: =A16+1 | K17: =IF(G17=0,0,J17/G17*100)
A18: =A17+1 | K18: =IF(G18=0,0,J18/G18*100)
A19: =A18+1 | K19: =IF(G19=0,0,J19/G19*100)
A20: =A19+1 | K20: =IF(G20=0,0,J20/G20*100)
... A35: =A34+1 | K35: =IF(G35=0,0,J35/G35*100)
A36: TOTAL | B36: N/A | C36: =SUM(C7:C35) | D36: N/A | F36: N/A | G36: =SUM(G7:G35) | H36: =SUM(H7:H35) | I36: =SUM(I7:I35) | J36: =SUM(J7:J35) | K36: =IF(G36=0,0,J36/G36*100) | L36: =SUM(L7:L35)

Sheet M.XX.DIX.BENEF.SIGN
B1: Nom de l'institution | C1: ='M.0.INFO.G'!C1
B2: Code de l'institution | C2: ='M.0.INFO.G'!C2
B3: Date des rapports | C3: ='M.0.INFO.G'!C3
B4: Rapport | C4: M.XX.DIX (10) BENEFICIAIRES PAR SIGNATURE LES PLUS IMPORTANTS
A6: N°. | B6: Nom et prénoms | C6: Date originale | D6: Montant original | E6: Solde | F6: Retard en capital | G6: Provision comptabilisée | H6: Garantie
A7: 1
A8: 2
A9: 3
A10: 4
A11: 5
A12: 6
A13: 7
A14: 8
A15: 9
A16: 10
A17: TOTAL | B17: N/A | C17: N/A | D17: =SUM(D7:D16) | E17: =SUM(E7:E16) | F17: =SUM(F7:F16) | G17: =SUM(G7:G16) | H17: =SUM(H7:H16)

Sheet M.XXI.BALANCES AGEES
B1: Nom de l'institution | C1: ='M.0.INFO.G'!C1
B2: Code de l'institution | C2: ='M.0.INFO.G'!C2
B3: Date des rapports | C3: ='M.0.INFO.G'!C3
B4: Rapport | C4: M.XXI.BALANCES AGEES DE CERTAINES SITUATIONS
C8: A)- DETTES AUPRES DU SECTEUR FINANCIER
A10: CODE | B10: ECHEANCES | C10: Nombre de dettes | D10: % | E10: Montant originel de la dette | F10: Capital restant dû | G10: %
A11: M.XXI.BAL.1 | B11: 1 Mois | D11: =IF($C$19=0,0,C11/$C$19) | G11: =IFERROR(F11/E11,0)
A12: M.XXI.BAL.2 | B12: 2 à 6 Mois | D12: =IF($C$19=0,0,C12/$C$19) | G12: =IFERROR(F12/E12,0)
A13: M.XXI.BAL.3 | B13: 7 à 12 Mois | D13: =IF($C$19=0,0,C13/$C$19) | G13: =IFERROR(F13/E13,0)
A14: M.XXI.BAL.4 | B14: 13 à 24 Mois | D14: =IF($C$19=0,0,C14/$C$19) | G14: =IFERROR(F14/E14,0)
A15: M.XXI.BAL.5 | B15: 25 à 36 Mois | D15: =IF($C$19=0,0,C15/$C$19) | G15: =IFERROR(F15/E15,0)
A16: M.XXI.BAL.6 | B16: 37 à 48 Mois | D16: =IF($C$19=0,0,C16/$C$19) | G16: =IFERROR(F16/E16,0)
A17: M.XXI.BAL.7 | B17: 49 à 60 Mois | D17: =IF($C$19=0,0,C17/$C$19) | G17: =IFERROR(F17/E17,0)
A18: M.XXI.BAL.8 | B18: Plus de 60 Mois | D18: =IF($C$19=0,0,C18/$C$19) | G18: =IFERROR(F18/E18,0)
A19: M.XXI.BAL.9 | B19: Total | C19: =C11+C12+C13+C14+C15+C16+C17+C18 | D19: =IF($C$19=0,0,C19/$C$19) | E19: =SUM(E11:E18) | F19: =F11+F12+F13+F14+F15+F16+F17+F18 | G19: =IFERROR(F19/E19,0)
C23: B)-PORTEFEUILLE DE CREDITS SAINS
A25: CODE | B25: ECHEANCES | C25: Nombres de Crédits | D25: % | E25: Montant originel du Crédit | F25: Capital restant dû | G25: %
A26: M.XXI.BAL.10 | B26: 1 Mois | C26: 4 | D26: =IF($C$34=0,0,C26/$C$34) | G26: =IFERROR(F26/E26,0)
A27: M.XXI.BAL.11 | B27: 2 à 6 Mois | C27: 7 | D27: =IF($C$34=0,0,C27/$C$34) | G27: =IFERROR(F27/E27,0)
A28: M.XXI.BAL.12 | B28: 7 à 12 Mois | C28: 8 | D28: =IF($C$34=0,0,C28/$C$34) | G28: =IFERROR(F28/E28,0)
A29: M.XXI.BAL.13 | B29: 13 à 24 Mois | C29: 5 | D29: =IF($C$34=0,0,C29/$C$34) | G29: =IFERROR(F29/E29,0)
A30: M.XXI.BAL.14 | B30: 25 à 36 Mois | D30: =IF($C$34=0,0,C30/$C$34) | G30: =IFERROR(F30/E30,0)
A31: M.XXI.BAL.15 | B31: 37 à 48 Mois | D31: =IF($C$34=0,0,C31/$C$34) | G31: =IFERROR(F31/E31,0)
A32: M.XXI.BAL.16 | B32: 49 à 60 Mois | D32: =IF($C$34=0,0,C32/$C$34) | G32: =IFERROR(F32/E32,0)
A33: M.XXI.BAL.17 | B33: Plus de 60 Mois | D33: =IF($C$34=0,0,C33/$C$34) | G33: =IFERROR(F33/E33,0)
A34: M.XXI.BAL.18 | B34: Total | C34: =C26+C27+C28+C29+C30+C31+C32+C33 | D34: =IF($C$34=0,0,C34/$C$34) | E34: =SUM(E26:E33) | F34: =F26+F27+F28+F29+F30+F31+F32+F33 | G34: =IFERROR(F34/E34,0)
C38: C)- DES DEPÔTS A TERME
A40: CODE | B40: ECHEANCES | C40: Nombres de DAT | D40: % | E40: Montant originel du DAT | F40: Montant en cours | G40: %
A41: M.XXI.BAL.19 | B41: 1 Mois | D41: =IF($C$49=0,0,C41/$C$49) | G41: =IFERROR(F41/E41,0)
A42: M.XXI.BAL.20 | B42: 2 à 6 Mois | D42: =IF($C$49=0,0,C42/$C$49) | G42: =IFERROR(F42/E42,0)
A43: M.XXI.BAL.21 | B43: 7 à 12 Mois | D43: =IF($C$49=0,0,C43/$C$49) | G43: =IFERROR(F43/E43,0)
A44: M.XXI.BAL.22 | B44: 13 à 24 Mois | D44: =IF($C$49=0,0,C44/$C$49) | G44: =IFERROR(F44/E44,0)
A45: M.XXI.BAL.23 | B45: 25 à 36 Mois | D45: =IF($C$49=0,0,C45/$C$49) | G45: =IFERROR(F45/E45,0)
A46: M.XXI.BAL.24 | B46: 37 à 48 Mois | D46: =IF($C$49=0,0,C46/$C$49) | G46: =IFERROR(F46/E46,0)
A47: M.XXI.BAL.25 | B47: 49 à 60 Mois | D47: =IF($C$49=0,0,C47/$C$49) | G47: =IFERROR(F47/E47,0)
A48: M.XXI.BAL.26 | B48: Plus de 60 Mois | D48: =IF($C$49=0,0,C48/$C$49) | G48: =IFERROR(F48/E48,0)
A49: M.XXI.BAL.27 | B49: Total | C49: =C41+C42+C43+C44+C45+C46+C47+C48 | D49: =IF($C$49=0,0,C49/$C$49) | E49: =SUM(E41:E48) | F49: =SUM(F41:F48) | G49: =IFERROR(F49/E49,0)
C53: D)-DES DEPÔTS DE GARANTIE
A55: CODE | B55: ECHEANCES | C55: Nombres de Dépôt de Garantie Financière | D55: % | E55: Montant Initial du Dépôt de garantie | F55: Montant en cours | G55: %
A56: M.XXI.BAL.28 | B56: 1 Mois | D56: =IF($C$64=0,0,C56/$C$64) | G56: =IFERROR(F56/E56,0)
...

Sheet M.XXII.INDIC.PRUDENTIELS
B1: Nom de l'institution | C1: ='M.0.INFO.G'!C1
B2: Code de l'institution | C2: ='M.0.INFO.G'!C2
B3: Date des rapports | C3: ='M.0.INFO.G'!C3
B4: Rapport | C4: M.XXII.INDICATEURS PRUDENTIELS
A6: N°. | B6: LIBELLE | C6: FORMULES | D6: RATIOS / VALEURS
A7: M.IND.IM.1 | B7: TAUX DE PERTE ANNUELLES SUR CREANCES | C7: MONTANT DES CREDITS PASSES EN PERTE DURANT LA PERIODE/MONTANT BRUT DU PORTEFEUILLE DE CREDITS DELA PERIODE | D7: =IF(C63=0,0,C62/C63*100)
A8: M.IND.IM.2 | B8: TAUX D'EXPOSITION | C8: CREDITS EN SOUFFRANCE NETS/FONDS PROPRES NETS | D8: =IF(+M.X.RSL!G39=0,0,+M.I.BILAN!F41/M.X.RSL!G39*100)
A9: M.IND.IM.3 | B9: COEFFICIENT D'EXPLOITATION | C9: FRAIS GENERAUX (FG)/PRODUITS FINANCIERS NETS (PFN) | D9: =IF(C66=0,0,C65/C66*100)
A10: M.IND.IM.4 | B10: RENDEMENT SUR ACTIF (AROA) | C10: RESULTAT D'EXPLOITATION HORS SUBVENTIONS (RE)/MONTANT MOYEN DE L'ACTIF POUR LA PERIODE | D10: =IF(C32=0,0, C58/C32*100)
A11: M.IND.IM.5 | B11: RENTABILITE DES FONDS PROPRES (AROE) | C11: RESULTAT D'EXPLOITATION HORS SUBVENTIONS (RE)/MONTANT MOYEN DES FONDS PROPRES POUR LA PERIODE | D11: =IF(C26=0,0,C58/C26*100)
A12: M.IND.IM.6 | B12: FRAIS GENERAUX (FG) | D12: =IFERROR(C65,0)
A13: M.IND.IM.7 | B13: PRODUITS FINANCIERS NETS (PFN) | D13: =IFERROR(C66,0)
A14: Total | B14: N/A | C14: N/A | D14: N/A
A19: DETERMINATION PREALABLE DES AGREGATS POUR LE CALCUL DES INDICATEURS PRUDENTIELS
B21: CALCUL DE LA MOYENNE DES FONDS PROPRES | C21: MONTANT
B22: FONDS PROPRES NETS Trimestre 1 (T1)
B23: FONDS PROPRES NETS T2
B24: FONDS PROPRES NETS T3
B25: FONDS PROPRES NET T4
B26: C | C26: =IFERROR(AVERAGE(C22:C25),0)
B27: TOTAL MOYEN DE L'ACTIF NET | C27: MONTANT
B28: TOTAL ACTIF NETS T1
B29: TOTAL ACTIF NETS T2
B30: TOTAL ACTIF NETS T3
B31: TOTAL ACTIF NETS T4
B32: D | C32: =IFERROR(AVERAGE(C28:C31),0)
B33: TOTAL MOYEN DE L'ACTIF BRUT | C33: MONTANT
B34: TOTAL ACTIF BRUT T1
B35: TOTAL ACTIF BRUT T2
B36: TOTAL ACTIF BRUT T3
B37: TOTAL ACTIF BRUT T4
B38: E | C38: =IFERROR(AVERAGE(C34:C37),0)
B42: CALCUL DU RESULTAT D'EXPLOITATION HORS SUBVENTION
A43: N°COMPTE | B43: INTITULE | C43: MONTANT
A44: 70 | B44: Produits Financiers liés aux Placements | C44: =M.II.RESULTAT!D62
A45: 71 | B45: Autres produits financiers | C45: =M.II.RESULTAT!D73
A46: 72 | B46: Produits liés à des comptes et opérations de ME | C46: =M.II.RESULTAT!D81
A47: 73 | B47: AUTRES PRODUITS NON FINANCIERS | C47: =M.II.RESULTAT!D88
A48: 76 | B48: REPRISE SUR AMORTISSEMENTS ET PROVISIOSNS | C48: =M.II.RESULTAT!D93
A49: 61 | B49: F | C49: =SUM(C44:C48)
...

Sheet M.XXII.RATIO.PRUDENTIELS
B1: Nom de l'institution | C1: ='M.0.INFO.G'!C1
B2: Code de l'institution | C2: ='M.0.INFO.G'!C2
B3: Date des rapports | C3: ='M.0.INFO.G'!C3
B4: Rapport | C4: M.XXII.RATIO.PRUDENTIELS
A6: N°. | B6: LIBELLE | C6: NORMES | D6: RATIOS / VALEURS
A7: M.RTP.IM.1 | B7: SOLVABILTE (RS) | C7: ≥ 15% | D7: =IFERROR(M.X.RSL!E58,0)
A8: M.RTP.IM.2 | B8: LIQUIDITE IMEDIATE (RLI) | C8: ≥ 20% | D8: =IFERROR(M.X.RSL!E66,0)
A9: M.RTP.IM.3 | B9: DIVERSIFICATION (RD) | C9: ≤ 5% | D9: =IFERROR(M.XIII.OATA!E10,0)
A10: M.RTP.IM.4 | B10: LIMITATION DES PARTICIPATIONS AUTRES QUE DANS LES IFI (RLP) | C10: ≤ 25% | D10: =IFERROR(M.XIII.OATA!E19,0)
A11: M.RTP.IM.5 | B11: COUVERTURE DES IMMOBILISATIONS PAR LES FPN (RCI) | C11: ≤ 50% | D11: =IFERROR(M.XIII.OATA!E31,0)
A12: M.RTP.IM.6 | B12: RESERVE LEGALE OBLIGATOIRE (RLO) | C12: ≥ 15 % | D12: =IFERROR(M.XIII.OATA!E44,0)
A13: M.RTP.IM.7 | B13: FONDS DE SOLIDARITE FINANCIERE FSF) | C13: ≥ 2% | D13: =IFERROR(M.XIV.FS!D18,0)
A14: M.RTP.IM.8 | B14: COUVERTURE DES EMPLOIS PAR LES RESSOURCES STABLES (RCERS) | C14: ≥ 100% | D14: =IFERROR(M.XVI.CERS!E32,0)
A15: M.RTP.IM.9 | B15: RATIOS DE TAUX DE PROVISION (RTP) | C15: ≥ 100% | D15: =IFERROR(M.XVII.PROV!G15,0)
A16: M.RTP.IM.10 | B16: RATIOS DE LIMITATION DES ENGAGEMENTS EN FAVEUR DES ACTIONNAIRES, DIRIGEANTS, ADMINISTRATEURS ET PERSONNEL | C16: ≤ 10% | D16: =IFERROR(((M.VI.ADM.DIR!F152+M.VII.PERSONNEL!E197)/M.X.RSL!G39)*100,0)
A17: Total | B17: N/A | C17: N/A | D17: N/A
A22: DETERMINATION PREALABLE DES AGREGATS POUR LE CALCUL DES INDICATEURS PRUDENTIELS
B24: CALCUL DE LA MOYENNE DES FONDS PROPRES | C24: MONTANT
B25: FONDS PROPRES NETS Trimestre 1 (T1) | C25: =+M.XXII.INDIC.PRUDENTIELS!C22
B26: FONDS PROPRES NETS T2 | C26: =+M.XXII.INDIC.PRUDENTIELS!C23
B27: FONDS PROPRES NETS T3 | C27: =+M.XXII.INDIC.PRUDENTIELS!C24
B28: FONDS PROPRES NET T4 | C28: =+M.XXII.INDIC.PRUDENTIELS!C25
B29: C | C29: =IFERROR(AVERAGE(C25:C28),"")
B30: TOTAL MOYEN DE L'ACTIF NET | C30: MONTANT
B31: TOTAL ACTIF NETS T1 | C31: =+M.XXII.INDIC.PRUDENTIELS!C28
B32: TOTAL ACTIF NETS T2 | C32: =+M.XXII.INDIC.PRUDENTIELS!C29
B33: TOTAL ACTIF NETS T3 | C33: =+M.XXII.INDIC.PRUDENTIELS!C30
B34: TOTAL ACTIF NETS T4 | C34: =+M.XXII.INDIC.PRUDENTIELS!C31
B35: D | C35: =IFERROR(AVERAGE(C31:C34),"")
B36: TOTAL MOYEN DE L'ACTIF BRUT | C36: MONTANT
B37: TOTAL ACTIF BRUT T1 | C37: =+M.XXII.INDIC.PRUDENTIELS!C34
B38: TOTAL ACTIF BRUT T2 | C38: =+M.XXII.INDIC.PRUDENTIELS!C35
B39: TOTAL ACTIF BRUT T3 | C39: =+M.XXII.INDIC.PRUDENTIELS!C36
B40: TOTAL ACTIF BRUT T4 | C40: =+M.XXII.INDIC.PRUDENTIELS!C37
B41: E | C41: =IFERROR(AVERAGE(C37:C40),"")
B45: CALCUL DU RESULTAT D'EXPLOITATION HORS SUBVENTION
A46: N°COMPTE | B46: INTITULE | C46: MONTANT
A47: 70 | B47: Produits Financiers liés aux Placements | C47: =M.II.RESULTAT!D62
A48: 71 | B48: Autres produits financiers | C48: =M.II.RESULTAT!D73
A49: 72 | B49: Produits liés à des comptes et opérations de ME | C49: =M.II.RESULTAT!D81
...

Sheet TAB_AUTRES_INDIC_1
B1: Nom de l'institution | C1: ='M.0.INFO.G'!C1
B2: Code de l'institution | C2: ='M.0.INFO.G'!C2
B3: Date des rapports | C3: ='M.0.INFO.G'!C3
B4: Rapport | C4: TABLEAU AUTRES INDICATEURS 1
A6: N°. | B6: LIBELLE | C6: NORMES | D6: RATIOS / VALEURS
A7: M.AI1.IM.1 | B7: FONDS PROPRES NETS (FPN) | C7: ≥ 15% | D7: =IFERROR(M.X.RSL!G39,0)
A8: M.AI1.IM.2 | B8: CREDITS AUX DIRIGEANTS | C8: ≥ 20% | D8: =IFERROR(M.VI.ADM.DIR!F152,0)
A9: M.AI1.IM.3 | B9: CREDITS AU PERSONNEL | C9: ≤ 5% | D9: =IFERROR(M.VII.PERSONNEL!E197,0)
A10: M.AI1.IM.4 | B10: SOLDE DES CREDITS DES DIX DEBITEURS | C10: ≤ 25% | D10: =IFERROR(M.VIII.DIX.DEB!E17,0)
A11: M.AI1.IM.5 | B11: DIX CREANCIERS LES PLUS IMPORTANTS | C11: ≤ 50% | D11: =IFERROR(M.XVIII.DIX.CREANCIERS!F17,0)
A12: M.AI1.IM.6 | B12: SOLDE DES CREDITS RESTRUCTURES | C12: ≥ 15 % | D12: =IFERROR(M.XIX.CREDITS.RESTRUCTURES!G36,0)
A13: M.AI1.IM.7 | B13: SOLDE DES DIX BENEFICIAIRES | C13: ≥ 2% | D13: =IFERROR(M.XX.DIX.BENEF.SIGN!E17,0)
A14: Total | B14: N/A | C14: N/A | D14: N/A

Sheet TAB_AUTRES_INDIC_2
B1: Nom de l'institution | C1: ='M.0.INFO.G'!C1
B2: Code de l'institution | C2: 001
B3: Date des rapports | C3: 31/03/2021
B4: Rapport | C4: TABLEAU AUTRES INDICATEURS 2
A6: N°. | B6: LIBELLE | C6: NORMES | D6: RATIOS / VALEURS
A7: M.AI2.IM.1 | B7: CREDITS NON RESIDENTS | D7: =M.XI.RPCS!I7
A8: M.AI2.IM.2 | B8: CREDITS AUX MENAGES | D8: =M.XI.RPCS!I8
A9: M.AI2.IM.3 | B9: CREDITS AUX ISBLSM | D9: =M.XI.RPCS!I9
A10: M.AI2.IM.4 | B10: AUTRES CREDITS | D10: =M.XI.RPCS!I10
A11: M.AI2.IM.5 | B11: ENCOURS CREDIT CONAKRY | D11: =M.XI.RPCS!I11
A12: M.AI2.IM.6 | B12: ENCOURS CREDIT BG | D12: =M.XI.RPCS!I22
A13: M.AI2.IM.7 | B13: ENCOURS CREDIT MG | D13: =M.XI.RPCS!I21
A14: M.AI2.IM.8 | B14: ENCOURS CREDIT HG | D14: =M.XI.RPCS!I24
A15: M.AI2.IM.9 | B15: ENCOURS CREDIT GF | D15: =M.XI.RPCS!I23
A16: Total | B16: N/A | C16: N/A | D16: N/A
